Number of bads in sentiment bad
68
Number of bads in sentiment good
3
Experiment:  0
Classifier nb
nbaccuracy on clean data 0.7291666666666666
nbaccuracy on tainted data 0.3875
nbACRA accuracy on tainted data var0 0.6916666666666667
nbACRA accuracy on tainted data var0.3 0.6958333333333333
Classifier nn
nnaccuracy on clean data 0.6208333333333333
nnaccuracy on tainted data 0.5125
nnACRA accuracy on tainted data var0 0.45416666666666666
nnACRA accuracy on tainted data var0.3 0.6041666666666666
Classifier svm
svmaccuracy on clean data 0.7041666666666667
svmaccuracy on tainted data 0.3375
svmACRA accuracy on tainted data var0 0.5208333333333334
svmACRA accuracy on tainted data var0.3 0.49583333333333335
Classifier lr
lraccuracy on clean data 0.7291666666666666
lraccuracy on tainted data 0.3541666666666667
lrACRA accuracy on tainted data var0 0.5583333333333333
lrACRA accuracy on tainted data var0.3 0.5583333333333333
Classifier rf
rfaccuracy on clean data 0.6875
rfaccuracy on tainted data 0.35
rfACRA accuracy on tainted data var0 0.7708333333333334
rfACRA accuracy on tainted data var0.3 0.8083333333333333
Writing Experiment  0
Experiment:  1
Classifier nb
nbaccuracy on clean data 0.6541666666666667
nbaccuracy on tainted data 0.2833333333333333
nbACRA accuracy on tainted data var0 0.6416666666666667
nbACRA accuracy on tainted data var0.3 0.6458333333333334
Classifier nn
nnaccuracy on clean data 0.65
nnaccuracy on tainted data 0.2833333333333333
nnACRA accuracy on tainted data var0 0.6875
nnACRA accuracy on tainted data var0.3 0.7
Classifier svm
svmaccuracy on clean data 0.6958333333333333
svmaccuracy on tainted data 0.2791666666666667
svmACRA accuracy on tainted data var0 0.45
svmACRA accuracy on tainted data var0.3 0.4166666666666667
Classifier lr
lraccuracy on clean data 0.6958333333333333
lraccuracy on tainted data 0.2875
lrACRA accuracy on tainted data var0 0.5208333333333334
lrACRA accuracy on tainted data var0.3 0.5208333333333334
Classifier rf
rfaccuracy on clean data 0.6833333333333333
rfaccuracy on tainted data 0.3
rfACRA accuracy on tainted data var0 0.7166666666666667
rfACRA accuracy on tainted data var0.3 0.7375
Writing Experiment  1
Experiment:  2
Classifier nb
nbaccuracy on clean data 0.75
nbaccuracy on tainted data 0.3333333333333333
nbACRA accuracy on tainted data var0 0.6333333333333333
nbACRA accuracy on tainted data var0.3 0.6458333333333334
Classifier nn
nnaccuracy on clean data 0.5333333333333333
nnaccuracy on tainted data 0.37916666666666665
nnACRA accuracy on tainted data var0 0.5125
nnACRA accuracy on tainted data var0.3 0.6625
Classifier svm
svmaccuracy on clean data 0.7291666666666666
svmaccuracy on tainted data 0.2916666666666667
svmACRA accuracy on tainted data var0 0.44583333333333336
svmACRA accuracy on tainted data var0.3 0.4708333333333333
Classifier lr
lraccuracy on clean data 0.7416666666666667
lraccuracy on tainted data 0.3125
lrACRA accuracy on tainted data var0 0.5625
lrACRA accuracy on tainted data var0.3 0.5625
Classifier rf
rfaccuracy on clean data 0.7166666666666667
rfaccuracy on tainted data 0.30833333333333335
rfACRA accuracy on tainted data var0 0.6791666666666667
rfACRA accuracy on tainted data var0.3 0.6583333333333333
Writing Experiment  2
Experiment:  3
Classifier nb
nbaccuracy on clean data 0.7166666666666667
nbaccuracy on tainted data 0.3375
nbACRA accuracy on tainted data var0 0.6416666666666667
nbACRA accuracy on tainted data var0.3 0.65
Classifier nn
nnaccuracy on clean data 0.7291666666666666
nnaccuracy on tainted data 0.3125
nnACRA accuracy on tainted data var0 0.6875
nnACRA accuracy on tainted data var0.3 0.6541666666666667
Classifier svm
svmaccuracy on clean data 0.7208333333333333
svmaccuracy on tainted data 0.3
svmACRA accuracy on tainted data var0 0.475
svmACRA accuracy on tainted data var0.3 0.4583333333333333
Classifier lr
lraccuracy on clean data 0.7291666666666666
lraccuracy on tainted data 0.31666666666666665
lrACRA accuracy on tainted data var0 0.5
lrACRA accuracy on tainted data var0.3 0.49583333333333335
Classifier rf
rfaccuracy on clean data 0.7291666666666666
rfaccuracy on tainted data 0.3333333333333333
rfACRA accuracy on tainted data var0 0.7375
rfACRA accuracy on tainted data var0.3 0.7833333333333333
Writing Experiment  3
Experiment:  4
Classifier nb
nbaccuracy on clean data 0.7375
nbaccuracy on tainted data 0.32916666666666666
nbACRA accuracy on tainted data var0 0.6375
nbACRA accuracy on tainted data var0.3 0.6625
Classifier nn
nnaccuracy on clean data 0.5833333333333334
nnaccuracy on tainted data 0.30416666666666664
nnACRA accuracy on tainted data var0 0.5
nnACRA accuracy on tainted data var0.3 0.5
Classifier svm
svmaccuracy on clean data 0.7375
svmaccuracy on tainted data 0.3
svmACRA accuracy on tainted data var0 0.5
svmACRA accuracy on tainted data var0.3 0.49583333333333335
Classifier lr
lraccuracy on clean data 0.7625
lraccuracy on tainted data 0.325
lrACRA accuracy on tainted data var0 0.49583333333333335
lrACRA accuracy on tainted data var0.3 0.5166666666666667
Classifier rf
rfaccuracy on clean data 0.7333333333333333
rfaccuracy on tainted data 0.32083333333333336
rfACRA accuracy on tainted data var0 0.75
rfACRA accuracy on tainted data var0.3 0.7416666666666667
Writing Experiment  4
Experiment:  5
Classifier nb
nbaccuracy on clean data 0.6958333333333333
nbaccuracy on tainted data 0.3375
nbACRA accuracy on tainted data var0 0.6625
nbACRA accuracy on tainted data var0.3 0.6833333333333333
Classifier nn
nnaccuracy on clean data 0.675
nnaccuracy on tainted data 0.3125
nnACRA accuracy on tainted data var0 0.7333333333333333
nnACRA accuracy on tainted data var0.3 0.7291666666666666
Classifier svm
svmaccuracy on clean data 0.7083333333333334
svmaccuracy on tainted data 0.30833333333333335
svmACRA accuracy on tainted data var0 0.5333333333333333
svmACRA accuracy on tainted data var0.3 0.475
Classifier lr
lraccuracy on clean data 0.725
lraccuracy on tainted data 0.32916666666666666
lrACRA accuracy on tainted data var0 0.5208333333333334
lrACRA accuracy on tainted data var0.3 0.5333333333333333
Classifier rf
rfaccuracy on clean data 0.7
rfaccuracy on tainted data 0.3333333333333333
rfACRA accuracy on tainted data var0 0.8
rfACRA accuracy on tainted data var0.3 0.7875
Writing Experiment  5
Experiment:  6
Classifier nb
nbaccuracy on clean data 0.7208333333333333
nbaccuracy on tainted data 0.36666666666666664
nbACRA accuracy on tainted data var0 0.7958333333333333
nbACRA accuracy on tainted data var0.3 0.8291666666666667
Classifier nn
nnaccuracy on clean data 0.7041666666666667
nnaccuracy on tainted data 0.37916666666666665
nnACRA accuracy on tainted data var0 0.7125
nnACRA accuracy on tainted data var0.3 0.7416666666666667
Classifier svm
svmaccuracy on clean data 0.7416666666666667
svmaccuracy on tainted data 0.37083333333333335
svmACRA accuracy on tainted data var0 0.4791666666666667
svmACRA accuracy on tainted data var0.3 0.4666666666666667
Classifier lr
lraccuracy on clean data 0.7541666666666667
lraccuracy on tainted data 0.38333333333333336
lrACRA accuracy on tainted data var0 0.5166666666666667
lrACRA accuracy on tainted data var0.3 0.5375
Classifier rf
rfaccuracy on clean data 0.7375
rfaccuracy on tainted data 0.4
rfACRA accuracy on tainted data var0 0.75
rfACRA accuracy on tainted data var0.3 0.725
Writing Experiment  6
Experiment:  7
Classifier nb
nbaccuracy on clean data 0.7041666666666667
nbaccuracy on tainted data 0.325
nbACRA accuracy on tainted data var0 0.825
nbACRA accuracy on tainted data var0.3 0.8083333333333333
Classifier nn
nnaccuracy on clean data 0.725
nnaccuracy on tainted data 0.36666666666666664
nnACRA accuracy on tainted data var0 0.7125
nnACRA accuracy on tainted data var0.3 0.6958333333333333
Classifier svm
svmaccuracy on clean data 0.7208333333333333
svmaccuracy on tainted data 0.32083333333333336
svmACRA accuracy on tainted data var0 0.45
svmACRA accuracy on tainted data var0.3 0.4666666666666667
Classifier lr
lraccuracy on clean data 0.7291666666666666
lraccuracy on tainted data 0.3375
lrACRA accuracy on tainted data var0 0.5416666666666666
lrACRA accuracy on tainted data var0.3 0.5333333333333333
Classifier rf
rfaccuracy on clean data 0.7291666666666666
rfaccuracy on tainted data 0.32916666666666666
rfACRA accuracy on tainted data var0 0.7375
rfACRA accuracy on tainted data var0.3 0.7166666666666667
Writing Experiment  7
Experiment:  8
Classifier nb
nbaccuracy on clean data 0.7375
nbaccuracy on tainted data 0.35833333333333334
nbACRA accuracy on tainted data var0 0.65


--------------------------------------------------------------------------------
LokyProcess-4525 failed with traceback: 
--------------------------------------------------------------------------------
Traceback (most recent call last):
  File "/LUSTRE/users/rnaveiro/.conda/envs/acra2/lib/python3.8/site-packages/joblib/externals/loky/backend/popen_loky_posix.py", line 199, in <module>
    exitcode = process_obj._bootstrap()
  File "/LUSTRE/users/rnaveiro/.conda/envs/acra2/lib/python3.8/multiprocessing/process.py", line 335, in _bootstrap
    util._flush_std_streams()
  File "/LUSTRE/users/rnaveiro/.conda/envs/acra2/lib/python3.8/multiprocessing/util.py", line 416, in _flush_std_streams
    sys.stderr.flush()
FileNotFoundError: [Errno 2] No such file or directory


--------------------------------------------------------------------------------


--------------------------------------------------------------------------------
LokyProcess-4527 failed with traceback: 
--------------------------------------------------------------------------------
Traceback (most recent call last):
  File "/LUSTRE/users/rnaveiro/.conda/envs/acra2/lib/python3.8/site-packages/joblib/externals/loky/backend/popen_loky_posix.py", line 199, in <module>
    exitcode = process_obj._bootstrap()
  File "/LUSTRE/users/rnaveiro/.conda/envs/acra2/lib/python3.8/multiprocessing/process.py", line 335, in _bootstrap
    util._flush_std_streams()
  File "/LUSTRE/users/rnaveiro/.conda/envs/acra2/lib/python3.8/multiprocessing/util.py", line 416, in _flush_std_streams
    sys.stderr.flush()
FileNotFoundError: [Errno 2] No such file or directory


--------------------------------------------------------------------------------


--------------------------------------------------------------------------------
LokyProcess-4491 failed with traceback: 
--------------------------------------------------------------------------------
Traceback (most recent call last):
  File "/LUSTRE/users/rnaveiro/.conda/envs/acra2/lib/python3.8/site-packages/joblib/externals/loky/backend/popen_loky_posix.py", line 199, in <module>
    exitcode = process_obj._bootstrap()
  File "/LUSTRE/users/rnaveiro/.conda/envs/acra2/lib/python3.8/multiprocessing/process.py", line 335, in _bootstrap
    util._flush_std_streams()
  File "/LUSTRE/users/rnaveiro/.conda/envs/acra2/lib/python3.8/multiprocessing/util.py", line 416, in _flush_std_streams
    sys.stderr.flush()
FileNotFoundError: [Errno 2] No such file or directory


--------------------------------------------------------------------------------


--------------------------------------------------------------------------------
LokyProcess-4503 failed with traceback: 
--------------------------------------------------------------------------------
Traceback (most recent call last):
  File "/LUSTRE/users/rnaveiro/.conda/envs/acra2/lib/python3.8/site-packages/joblib/externals/loky/backend/popen_loky_posix.py", line 199, in <module>
    exitcode = process_obj._bootstrap()
  File "/LUSTRE/users/rnaveiro/.conda/envs/acra2/lib/python3.8/multiprocessing/process.py", line 335, in _bootstrap
    util._flush_std_streams()
  File "/LUSTRE/users/rnaveiro/.conda/envs/acra2/lib/python3.8/multiprocessing/util.py", line 416, in _flush_std_streams
    sys.stderr.flush()
FileNotFoundError: [Errno 2] No such file or directory


--------------------------------------------------------------------------------


--------------------------------------------------------------------------------
LokyProcess-4514 failed with traceback: 
--------------------------------------------------------------------------------
Traceback (most recent call last):
  File "/LUSTRE/users/rnaveiro/.conda/envs/acra2/lib/python3.8/site-packages/joblib/externals/loky/backend/popen_loky_posix.py", line 199, in <module>
    exitcode = process_obj._bootstrap()
  File "/LUSTRE/users/rnaveiro/.conda/envs/acra2/lib/python3.8/multiprocessing/process.py", line 335, in _bootstrap
    util._flush_std_streams()
  File "/LUSTRE/users/rnaveiro/.conda/envs/acra2/lib/python3.8/multiprocessing/util.py", line 416, in _flush_std_streams
    sys.stderr.flush()
FileNotFoundError: [Errno 2] No such file or directory


--------------------------------------------------------------------------------


--------------------------------------------------------------------------------
LokyProcess-4509 failed with traceback: 
--------------------------------------------------------------------------------
Traceback (most recent call last):
  File "/LUSTRE/users/rnaveiro/.conda/envs/acra2/lib/python3.8/site-packages/joblib/externals/loky/backend/popen_loky_posix.py", line 199, in <module>
    exitcode = process_obj._bootstrap()
  File "/LUSTRE/users/rnaveiro/.conda/envs/acra2/lib/python3.8/multiprocessing/process.py", line 335, in _bootstrap
    util._flush_std_streams()
  File "/LUSTRE/users/rnaveiro/.conda/envs/acra2/lib/python3.8/multiprocessing/util.py", line 416, in _flush_std_streams
    sys.stderr.flush()
FileNotFoundError: [Errno 2] No such file or directory


--------------------------------------------------------------------------------


--------------------------------------------------------------------------------
LokyProcess-4512 failed with traceback: 
--------------------------------------------------------------------------------
Traceback (most recent call last):
  File "/LUSTRE/users/rnaveiro/.conda/envs/acra2/lib/python3.8/site-packages/joblib/externals/loky/backend/popen_loky_posix.py", line 199, in <module>
    exitcode = process_obj._bootstrap()
  File "/LUSTRE/users/rnaveiro/.conda/envs/acra2/lib/python3.8/multiprocessing/process.py", line 335, in _bootstrap
    util._flush_std_streams()
  File "/LUSTRE/users/rnaveiro/.conda/envs/acra2/lib/python3.8/multiprocessing/util.py", line 416, in _flush_std_streams
    sys.stderr.flush()
FileNotFoundError: [Errno 2] No such file or directory


--------------------------------------------------------------------------------


--------------------------------------------------------------------------------
LokyProcess-4535 failed with traceback: 
--------------------------------------------------------------------------------
Traceback (most recent call last):
  File "/LUSTRE/users/rnaveiro/.conda/envs/acra2/lib/python3.8/site-packages/joblib/externals/loky/backend/popen_loky_posix.py", line 199, in <module>
    exitcode = process_obj._bootstrap()
  File "/LUSTRE/users/rnaveiro/.conda/envs/acra2/lib/python3.8/multiprocessing/process.py", line 335, in _bootstrap
    util._flush_std_streams()
  File "/LUSTRE/users/rnaveiro/.conda/envs/acra2/lib/python3.8/multiprocessing/util.py", line 416, in _flush_std_streams
    sys.stderr.flush()
FileNotFoundError: [Errno 2] No such file or directory


--------------------------------------------------------------------------------


--------------------------------------------------------------------------------
LokyProcess-4529 failed with traceback: 
--------------------------------------------------------------------------------
Traceback (most recent call last):
  File "/LUSTRE/users/rnaveiro/.conda/envs/acra2/lib/python3.8/site-packages/joblib/externals/loky/backend/popen_loky_posix.py", line 199, in <module>
    exitcode = process_obj._bootstrap()
  File "/LUSTRE/users/rnaveiro/.conda/envs/acra2/lib/python3.8/multiprocessing/process.py", line 335, in _bootstrap
    util._flush_std_streams()
  File "/LUSTRE/users/rnaveiro/.conda/envs/acra2/lib/python3.8/multiprocessing/util.py", line 416, in _flush_std_streams
    sys.stderr.flush()
FileNotFoundError: [Errno 2] No such file or directory


--------------------------------------------------------------------------------


--------------------------------------------------------------------------------
LokyProcess-4490 failed with traceback: 
--------------------------------------------------------------------------------
Traceback (most recent call last):
  File "/LUSTRE/users/rnaveiro/.conda/envs/acra2/lib/python3.8/site-packages/joblib/externals/loky/backend/popen_loky_posix.py", line 199, in <module>
    exitcode = process_obj._bootstrap()
  File "/LUSTRE/users/rnaveiro/.conda/envs/acra2/lib/python3.8/multiprocessing/process.py", line 335, in _bootstrap
    util._flush_std_streams()
  File "/LUSTRE/users/rnaveiro/.conda/envs/acra2/lib/python3.8/multiprocessing/util.py", line 416, in _flush_std_streams
    sys.stderr.flush()
FileNotFoundError: [Errno 2] No such file or directory


--------------------------------------------------------------------------------


--------------------------------------------------------------------------------
LokyProcess-4532 failed with traceback: 
--------------------------------------------------------------------------------
Traceback (most recent call last):
  File "/LUSTRE/users/rnaveiro/.conda/envs/acra2/lib/python3.8/site-packages/joblib/externals/loky/backend/popen_loky_posix.py", line 199, in <module>
    exitcode = process_obj._bootstrap()
  File "/LUSTRE/users/rnaveiro/.conda/envs/acra2/lib/python3.8/multiprocessing/process.py", line 335, in _bootstrap
    util._flush_std_streams()
  File "/LUSTRE/users/rnaveiro/.conda/envs/acra2/lib/python3.8/multiprocessing/util.py", line 416, in _flush_std_streams
    sys.stderr.flush()
FileNotFoundError: [Errno 2] No such file or directory


--------------------------------------------------------------------------------


--------------------------------------------------------------------------------
LokyProcess-4496 failed with traceback: 
--------------------------------------------------------------------------------
Traceback (most recent call last):
  File "/LUSTRE/users/rnaveiro/.conda/envs/acra2/lib/python3.8/site-packages/joblib/externals/loky/backend/popen_loky_posix.py", line 199, in <module>
    exitcode = process_obj._bootstrap()
  File "/LUSTRE/users/rnaveiro/.conda/envs/acra2/lib/python3.8/multiprocessing/process.py", line 335, in _bootstrap
    util._flush_std_streams()
  File "/LUSTRE/users/rnaveiro/.conda/envs/acra2/lib/python3.8/multiprocessing/util.py", line 416, in _flush_std_streams
    sys.stderr.flush()
FileNotFoundError: [Errno 2] No such file or directory


--------------------------------------------------------------------------------


--------------------------------------------------------------------------------
LokyProcess-4500 failed with traceback: 
--------------------------------------------------------------------------------
Traceback (most recent call last):
  File "/LUSTRE/users/rnaveiro/.conda/envs/acra2/lib/python3.8/site-packages/joblib/externals/loky/backend/popen_loky_posix.py", line 199, in <module>
    exitcode = process_obj._bootstrap()
  File "/LUSTRE/users/rnaveiro/.conda/envs/acra2/lib/python3.8/multiprocessing/process.py", line 335, in _bootstrap
    util._flush_std_streams()
  File "/LUSTRE/users/rnaveiro/.conda/envs/acra2/lib/python3.8/multiprocessing/util.py", line 416, in _flush_std_streams
    sys.stderr.flush()
FileNotFoundError: [Errno 2] No such file or directory


--------------------------------------------------------------------------------


--------------------------------------------------------------------------------
LokyProcess-4528 failed with traceback: 
--------------------------------------------------------------------------------
Traceback (most recent call last):
  File "/LUSTRE/users/rnaveiro/.conda/envs/acra2/lib/python3.8/site-packages/joblib/externals/loky/backend/popen_loky_posix.py", line 199, in <module>
    exitcode = process_obj._bootstrap()
  File "/LUSTRE/users/rnaveiro/.conda/envs/acra2/lib/python3.8/multiprocessing/process.py", line 335, in _bootstrap
    util._flush_std_streams()
  File "/LUSTRE/users/rnaveiro/.conda/envs/acra2/lib/python3.8/multiprocessing/util.py", line 416, in _flush_std_streams
    sys.stderr.flush()
FileNotFoundError: [Errno 2] No such file or directory


--------------------------------------------------------------------------------


--------------------------------------------------------------------------------
LokyProcess-4505 failed with traceback: 
--------------------------------------------------------------------------------
Traceback (most recent call last):
  File "/LUSTRE/users/rnaveiro/.conda/envs/acra2/lib/python3.8/site-packages/joblib/externals/loky/backend/popen_loky_posix.py", line 199, in <module>
    exitcode = process_obj._bootstrap()
  File "/LUSTRE/users/rnaveiro/.conda/envs/acra2/lib/python3.8/multiprocessing/process.py", line 335, in _bootstrap
    util._flush_std_streams()
  File "/LUSTRE/users/rnaveiro/.conda/envs/acra2/lib/python3.8/multiprocessing/util.py", line 416, in _flush_std_streams
    sys.stderr.flush()
FileNotFoundError: [Errno 2] No such file or directory


--------------------------------------------------------------------------------


--------------------------------------------------------------------------------
LokyProcess-4501 failed with traceback: 
--------------------------------------------------------------------------------
Traceback (most recent call last):
  File "/LUSTRE/users/rnaveiro/.conda/envs/acra2/lib/python3.8/site-packages/joblib/externals/loky/backend/popen_loky_posix.py", line 199, in <module>
    exitcode = process_obj._bootstrap()
  File "/LUSTRE/users/rnaveiro/.conda/envs/acra2/lib/python3.8/multiprocessing/process.py", line 335, in _bootstrap
    util._flush_std_streams()
  File "/LUSTRE/users/rnaveiro/.conda/envs/acra2/lib/python3.8/multiprocessing/util.py", line 416, in _flush_std_streams
    sys.stderr.flush()
FileNotFoundError: [Errno 2] No such file or directory


--------------------------------------------------------------------------------


--------------------------------------------------------------------------------
LokyProcess-4533 failed with traceback: 
--------------------------------------------------------------------------------
Traceback (most recent call last):
  File "/LUSTRE/users/rnaveiro/.conda/envs/acra2/lib/python3.8/site-packages/joblib/externals/loky/backend/popen_loky_posix.py", line 199, in <module>
    exitcode = process_obj._bootstrap()
  File "/LUSTRE/users/rnaveiro/.conda/envs/acra2/lib/python3.8/multiprocessing/process.py", line 335, in _bootstrap
    util._flush_std_streams()
  File "/LUSTRE/users/rnaveiro/.conda/envs/acra2/lib/python3.8/multiprocessing/util.py", line 416, in _flush_std_streams
    sys.stderr.flush()
FileNotFoundError: [Errno 2] No such file or directory


--------------------------------------------------------------------------------


--------------------------------------------------------------------------------
LokyProcess-4506 failed with traceback: 
--------------------------------------------------------------------------------
Traceback (most recent call last):
  File "/LUSTRE/users/rnaveiro/.conda/envs/acra2/lib/python3.8/site-packages/joblib/externals/loky/backend/popen_loky_posix.py", line 199, in <module>
    exitcode = process_obj._bootstrap()
  File "/LUSTRE/users/rnaveiro/.conda/envs/acra2/lib/python3.8/multiprocessing/process.py", line 335, in _bootstrap
    util._flush_std_streams()
  File "/LUSTRE/users/rnaveiro/.conda/envs/acra2/lib/python3.8/multiprocessing/util.py", line 416, in _flush_std_streams
    sys.stderr.flush()
FileNotFoundError: [Errno 2] No such file or directory


--------------------------------------------------------------------------------


--------------------------------------------------------------------------------
LokyProcess-4524 failed with traceback: 
--------------------------------------------------------------------------------
Traceback (most recent call last):
  File "/LUSTRE/users/rnaveiro/.conda/envs/acra2/lib/python3.8/site-packages/joblib/externals/loky/backend/popen_loky_posix.py", line 199, in <module>
    exitcode = process_obj._bootstrap()
  File "/LUSTRE/users/rnaveiro/.conda/envs/acra2/lib/python3.8/multiprocessing/process.py", line 335, in _bootstrap
    util._flush_std_streams()
  File "/LUSTRE/users/rnaveiro/.conda/envs/acra2/lib/python3.8/multiprocessing/util.py", line 416, in _flush_std_streams
    sys.stderr.flush()
FileNotFoundError: [Errno 2] No such file or directory


--------------------------------------------------------------------------------


--------------------------------------------------------------------------------
LokyProcess-4536 failed with traceback: 
--------------------------------------------------------------------------------
Traceback (most recent call last):
  File "/LUSTRE/users/rnaveiro/.conda/envs/acra2/lib/python3.8/site-packages/joblib/externals/loky/backend/popen_loky_posix.py", line 199, in <module>
    exitcode = process_obj._bootstrap()
  File "/LUSTRE/users/rnaveiro/.conda/envs/acra2/lib/python3.8/multiprocessing/process.py", line 335, in _bootstrap
    util._flush_std_streams()
  File "/LUSTRE/users/rnaveiro/.conda/envs/acra2/lib/python3.8/multiprocessing/util.py", line 416, in _flush_std_streams
    sys.stderr.flush()
FileNotFoundError: [Errno 2] No such file or directory


--------------------------------------------------------------------------------


--------------------------------------------------------------------------------
LokyProcess-4530 failed with traceback: 
--------------------------------------------------------------------------------
Traceback (most recent call last):
  File "/LUSTRE/users/rnaveiro/.conda/envs/acra2/lib/python3.8/site-packages/joblib/externals/loky/backend/popen_loky_posix.py", line 199, in <module>
    exitcode = process_obj._bootstrap()
  File "/LUSTRE/users/rnaveiro/.conda/envs/acra2/lib/python3.8/multiprocessing/process.py", line 335, in _bootstrap
    util._flush_std_streams()
  File "/LUSTRE/users/rnaveiro/.conda/envs/acra2/lib/python3.8/multiprocessing/util.py", line 416, in _flush_std_streams
    sys.stderr.flush()
FileNotFoundError: [Errno 2] No such file or directory


--------------------------------------------------------------------------------


--------------------------------------------------------------------------------
LokyProcess-4508 failed with traceback: 
--------------------------------------------------------------------------------
Traceback (most recent call last):
  File "/LUSTRE/users/rnaveiro/.conda/envs/acra2/lib/python3.8/site-packages/joblib/externals/loky/backend/popen_loky_posix.py", line 199, in <module>
    exitcode = process_obj._bootstrap()
  File "/LUSTRE/users/rnaveiro/.conda/envs/acra2/lib/python3.8/multiprocessing/process.py", line 335, in _bootstrap
    util._flush_std_streams()
  File "/LUSTRE/users/rnaveiro/.conda/envs/acra2/lib/python3.8/multiprocessing/util.py", line 416, in _flush_std_streams
    sys.stderr.flush()
FileNotFoundError: [Errno 2] No such file or directory


--------------------------------------------------------------------------------


--------------------------------------------------------------------------------
LokyProcess-4492 failed with traceback: 
--------------------------------------------------------------------------------
Traceback (most recent call last):
  File "/LUSTRE/users/rnaveiro/.conda/envs/acra2/lib/python3.8/site-packages/joblib/externals/loky/backend/popen_loky_posix.py", line 199, in <module>
    exitcode = process_obj._bootstrap()
  File "/LUSTRE/users/rnaveiro/.conda/envs/acra2/lib/python3.8/multiprocessing/process.py", line 335, in _bootstrap
    util._flush_std_streams()
  File "/LUSTRE/users/rnaveiro/.conda/envs/acra2/lib/python3.8/multiprocessing/util.py", line 416, in _flush_std_streams
    sys.stderr.flush()
FileNotFoundError: [Errno 2] No such file or directory


--------------------------------------------------------------------------------


--------------------------------------------------------------------------------
LokyProcess-4531 failed with traceback: 
--------------------------------------------------------------------------------
Traceback (most recent call last):
  File "/LUSTRE/users/rnaveiro/.conda/envs/acra2/lib/python3.8/site-packages/joblib/externals/loky/backend/popen_loky_posix.py", line 199, in <module>
    exitcode = process_obj._bootstrap()
  File "/LUSTRE/users/rnaveiro/.conda/envs/acra2/lib/python3.8/multiprocessing/process.py", line 335, in _bootstrap
    util._flush_std_streams()
  File "/LUSTRE/users/rnaveiro/.conda/envs/acra2/lib/python3.8/multiprocessing/util.py", line 416, in _flush_std_streams
    sys.stderr.flush()
FileNotFoundError: [Errno 2] No such file or directory


--------------------------------------------------------------------------------


--------------------------------------------------------------------------------
LokyProcess-4510 failed with traceback: 
--------------------------------------------------------------------------------
Traceback (most recent call last):
  File "/LUSTRE/users/rnaveiro/.conda/envs/acra2/lib/python3.8/site-packages/joblib/externals/loky/backend/popen_loky_posix.py", line 199, in <module>
    exitcode = process_obj._bootstrap()
  File "/LUSTRE/users/rnaveiro/.conda/envs/acra2/lib/python3.8/multiprocessing/process.py", line 335, in _bootstrap
    util._flush_std_streams()
  File "/LUSTRE/users/rnaveiro/.conda/envs/acra2/lib/python3.8/multiprocessing/util.py", line 416, in _flush_std_streams
    sys.stderr.flush()
FileNotFoundError: [Errno 2] No such file or directory


--------------------------------------------------------------------------------


--------------------------------------------------------------------------------
LokyProcess-4499 failed with traceback: 
--------------------------------------------------------------------------------
Traceback (most recent call last):
  File "/LUSTRE/users/rnaveiro/.conda/envs/acra2/lib/python3.8/site-packages/joblib/externals/loky/backend/popen_loky_posix.py", line 199, in <module>
    exitcode = process_obj._bootstrap()
  File "/LUSTRE/users/rnaveiro/.conda/envs/acra2/lib/python3.8/multiprocessing/process.py", line 335, in _bootstrap
    util._flush_std_streams()
  File "/LUSTRE/users/rnaveiro/.conda/envs/acra2/lib/python3.8/multiprocessing/util.py", line 416, in _flush_std_streams
    sys.stderr.flush()
FileNotFoundError: [Errno 2] No such file or directory


--------------------------------------------------------------------------------


--------------------------------------------------------------------------------
LokyProcess-4517 failed with traceback: 
--------------------------------------------------------------------------------
Traceback (most recent call last):
  File "/LUSTRE/users/rnaveiro/.conda/envs/acra2/lib/python3.8/site-packages/joblib/externals/loky/backend/popen_loky_posix.py", line 199, in <module>
    exitcode = process_obj._bootstrap()
  File "/LUSTRE/users/rnaveiro/.conda/envs/acra2/lib/python3.8/multiprocessing/process.py", line 335, in _bootstrap
    util._flush_std_streams()
  File "/LUSTRE/users/rnaveiro/.conda/envs/acra2/lib/python3.8/multiprocessing/util.py", line 416, in _flush_std_streams
    sys.stderr.flush()
FileNotFoundError: [Errno 2] No such file or directory


--------------------------------------------------------------------------------


--------------------------------------------------------------------------------
LokyProcess-4516 failed with traceback: 
--------------------------------------------------------------------------------
Traceback (most recent call last):
  File "/LUSTRE/users/rnaveiro/.conda/envs/acra2/lib/python3.8/site-packages/joblib/externals/loky/backend/popen_loky_posix.py", line 199, in <module>
    exitcode = process_obj._bootstrap()
  File "/LUSTRE/users/rnaveiro/.conda/envs/acra2/lib/python3.8/multiprocessing/process.py", line 335, in _bootstrap
    util._flush_std_streams()
  File "/LUSTRE/users/rnaveiro/.conda/envs/acra2/lib/python3.8/multiprocessing/util.py", line 416, in _flush_std_streams
    sys.stderr.flush()
FileNotFoundError: [Errno 2] No such file or directory


--------------------------------------------------------------------------------


--------------------------------------------------------------------------------
LokyProcess-4497 failed with traceback: 
--------------------------------------------------------------------------------
Traceback (most recent call last):
  File "/LUSTRE/users/rnaveiro/.conda/envs/acra2/lib/python3.8/site-packages/joblib/externals/loky/backend/popen_loky_posix.py", line 199, in <module>
    exitcode = process_obj._bootstrap()
  File "/LUSTRE/users/rnaveiro/.conda/envs/acra2/lib/python3.8/multiprocessing/process.py", line 335, in _bootstrap
    util._flush_std_streams()
  File "/LUSTRE/users/rnaveiro/.conda/envs/acra2/lib/python3.8/multiprocessing/util.py", line 416, in _flush_std_streams
    sys.stderr.flush()
FileNotFoundError: [Errno 2] No such file or directory


--------------------------------------------------------------------------------


--------------------------------------------------------------------------------
LokyProcess-4511 failed with traceback: 
--------------------------------------------------------------------------------
Traceback (most recent call last):
  File "/LUSTRE/users/rnaveiro/.conda/envs/acra2/lib/python3.8/site-packages/joblib/externals/loky/backend/popen_loky_posix.py", line 199, in <module>
    exitcode = process_obj._bootstrap()
  File "/LUSTRE/users/rnaveiro/.conda/envs/acra2/lib/python3.8/multiprocessing/process.py", line 335, in _bootstrap
    util._flush_std_streams()
  File "/LUSTRE/users/rnaveiro/.conda/envs/acra2/lib/python3.8/multiprocessing/util.py", line 416, in _flush_std_streams
    sys.stderr.flush()
FileNotFoundError: [Errno 2] No such file or directory


--------------------------------------------------------------------------------


--------------------------------------------------------------------------------
LokyProcess-4519 failed with traceback: 
--------------------------------------------------------------------------------
Traceback (most recent call last):
  File "/LUSTRE/users/rnaveiro/.conda/envs/acra2/lib/python3.8/site-packages/joblib/externals/loky/backend/popen_loky_posix.py", line 199, in <module>
    exitcode = process_obj._bootstrap()
  File "/LUSTRE/users/rnaveiro/.conda/envs/acra2/lib/python3.8/multiprocessing/process.py", line 335, in _bootstrap
    util._flush_std_streams()
  File "/LUSTRE/users/rnaveiro/.conda/envs/acra2/lib/python3.8/multiprocessing/util.py", line 416, in _flush_std_streams
    sys.stderr.flush()
FileNotFoundError: [Errno 2] No such file or directory


--------------------------------------------------------------------------------


--------------------------------------------------------------------------------
LokyProcess-4455 failed with traceback: 
--------------------------------------------------------------------------------
Traceback (most recent call last):
  File "/LUSTRE/users/rnaveiro/.conda/envs/acra2/lib/python3.8/site-packages/joblib/externals/loky/backend/popen_loky_posix.py", line 199, in <module>
    exitcode = process_obj._bootstrap()
  File "/LUSTRE/users/rnaveiro/.conda/envs/acra2/lib/python3.8/multiprocessing/process.py", line 335, in _bootstrap
    util._flush_std_streams()
  File "/LUSTRE/users/rnaveiro/.conda/envs/acra2/lib/python3.8/multiprocessing/util.py", line 416, in _flush_std_streams
    sys.stderr.flush()
FileNotFoundError: [Errno 2] No such file or directory


--------------------------------------------------------------------------------


--------------------------------------------------------------------------------
LokyProcess-4502 failed with traceback: 
--------------------------------------------------------------------------------
Traceback (most recent call last):
  File "/LUSTRE/users/rnaveiro/.conda/envs/acra2/lib/python3.8/site-packages/joblib/externals/loky/backend/popen_loky_posix.py", line 199, in <module>
    exitcode = process_obj._bootstrap()
  File "/LUSTRE/users/rnaveiro/.conda/envs/acra2/lib/python3.8/multiprocessing/process.py", line 335, in _bootstrap
    util._flush_std_streams()
  File "/LUSTRE/users/rnaveiro/.conda/envs/acra2/lib/python3.8/multiprocessing/util.py", line 416, in _flush_std_streams
    sys.stderr.flush()
FileNotFoundError: [Errno 2] No such file or directory


--------------------------------------------------------------------------------


--------------------------------------------------------------------------------
LokyProcess-4515 failed with traceback: 
--------------------------------------------------------------------------------
Traceback (most recent call last):
  File "/LUSTRE/users/rnaveiro/.conda/envs/acra2/lib/python3.8/site-packages/joblib/externals/loky/backend/popen_loky_posix.py", line 199, in <module>
    exitcode = process_obj._bootstrap()
  File "/LUSTRE/users/rnaveiro/.conda/envs/acra2/lib/python3.8/multiprocessing/process.py", line 335, in _bootstrap
    util._flush_std_streams()
  File "/LUSTRE/users/rnaveiro/.conda/envs/acra2/lib/python3.8/multiprocessing/util.py", line 416, in _flush_std_streams
    sys.stderr.flush()
FileNotFoundError: [Errno 2] No such file or directory


--------------------------------------------------------------------------------


--------------------------------------------------------------------------------
LokyProcess-4495 failed with traceback: 
--------------------------------------------------------------------------------
Traceback (most recent call last):
  File "/LUSTRE/users/rnaveiro/.conda/envs/acra2/lib/python3.8/site-packages/joblib/externals/loky/backend/popen_loky_posix.py", line 199, in <module>
    exitcode = process_obj._bootstrap()
  File "/LUSTRE/users/rnaveiro/.conda/envs/acra2/lib/python3.8/multiprocessing/process.py", line 335, in _bootstrap
    util._flush_std_streams()
  File "/LUSTRE/users/rnaveiro/.conda/envs/acra2/lib/python3.8/multiprocessing/util.py", line 416, in _flush_std_streams
    sys.stderr.flush()
FileNotFoundError: [Errno 2] No such file or directory


--------------------------------------------------------------------------------


--------------------------------------------------------------------------------
LokyProcess-4520 failed with traceback: 
--------------------------------------------------------------------------------
Traceback (most recent call last):
  File "/LUSTRE/users/rnaveiro/.conda/envs/acra2/lib/python3.8/site-packages/joblib/externals/loky/backend/popen_loky_posix.py", line 199, in <module>
    exitcode = process_obj._bootstrap()
  File "/LUSTRE/users/rnaveiro/.conda/envs/acra2/lib/python3.8/multiprocessing/process.py", line 335, in _bootstrap
    util._flush_std_streams()
  File "/LUSTRE/users/rnaveiro/.conda/envs/acra2/lib/python3.8/multiprocessing/util.py", line 416, in _flush_std_streams
    sys.stderr.flush()
FileNotFoundError: [Errno 2] No such file or directory


--------------------------------------------------------------------------------


--------------------------------------------------------------------------------
LokyProcess-4507 failed with traceback: 
--------------------------------------------------------------------------------
Traceback (most recent call last):
  File "/LUSTRE/users/rnaveiro/.conda/envs/acra2/lib/python3.8/site-packages/joblib/externals/loky/backend/popen_loky_posix.py", line 199, in <module>
    exitcode = process_obj._bootstrap()
  File "/LUSTRE/users/rnaveiro/.conda/envs/acra2/lib/python3.8/multiprocessing/process.py", line 335, in _bootstrap
    util._flush_std_streams()
  File "/LUSTRE/users/rnaveiro/.conda/envs/acra2/lib/python3.8/multiprocessing/util.py", line 416, in _flush_std_streams
    sys.stderr.flush()
FileNotFoundError: [Errno 2] No such file or directory


--------------------------------------------------------------------------------


--------------------------------------------------------------------------------
LokyProcess-4493 failed with traceback: 
--------------------------------------------------------------------------------
Traceback (most recent call last):
  File "/LUSTRE/users/rnaveiro/.conda/envs/acra2/lib/python3.8/site-packages/joblib/externals/loky/backend/popen_loky_posix.py", line 199, in <module>
    exitcode = process_obj._bootstrap()
  File "/LUSTRE/users/rnaveiro/.conda/envs/acra2/lib/python3.8/multiprocessing/process.py", line 335, in _bootstrap
    util._flush_std_streams()
  File "/LUSTRE/users/rnaveiro/.conda/envs/acra2/lib/python3.8/multiprocessing/util.py", line 416, in _flush_std_streams
    sys.stderr.flush()
FileNotFoundError: [Errno 2] No such file or directory


--------------------------------------------------------------------------------


--------------------------------------------------------------------------------
LokyProcess-4523 failed with traceback: 
--------------------------------------------------------------------------------
Traceback (most recent call last):
  File "/LUSTRE/users/rnaveiro/.conda/envs/acra2/lib/python3.8/site-packages/joblib/externals/loky/backend/popen_loky_posix.py", line 199, in <module>
    exitcode = process_obj._bootstrap()
  File "/LUSTRE/users/rnaveiro/.conda/envs/acra2/lib/python3.8/multiprocessing/process.py", line 335, in _bootstrap
    util._flush_std_streams()
  File "/LUSTRE/users/rnaveiro/.conda/envs/acra2/lib/python3.8/multiprocessing/util.py", line 416, in _flush_std_streams
    sys.stderr.flush()
FileNotFoundError: [Errno 2] No such file or directory


--------------------------------------------------------------------------------


--------------------------------------------------------------------------------
LokyProcess-4526 failed with traceback: 
--------------------------------------------------------------------------------
Traceback (most recent call last):
  File "/LUSTRE/users/rnaveiro/.conda/envs/acra2/lib/python3.8/site-packages/joblib/externals/loky/backend/popen_loky_posix.py", line 199, in <module>
    exitcode = process_obj._bootstrap()
  File "/LUSTRE/users/rnaveiro/.conda/envs/acra2/lib/python3.8/multiprocessing/process.py", line 335, in _bootstrap
    util._flush_std_streams()
  File "/LUSTRE/users/rnaveiro/.conda/envs/acra2/lib/python3.8/multiprocessing/util.py", line 416, in _flush_std_streams
    sys.stderr.flush()
FileNotFoundError: [Errno 2] No such file or directory


--------------------------------------------------------------------------------


--------------------------------------------------------------------------------
LokyProcess-4522 failed with traceback: 
--------------------------------------------------------------------------------
Traceback (most recent call last):
  File "/LUSTRE/users/rnaveiro/.conda/envs/acra2/lib/python3.8/site-packages/joblib/externals/loky/backend/popen_loky_posix.py", line 199, in <module>
    exitcode = process_obj._bootstrap()
  File "/LUSTRE/users/rnaveiro/.conda/envs/acra2/lib/python3.8/multiprocessing/process.py", line 335, in _bootstrap
    util._flush_std_streams()
  File "/LUSTRE/users/rnaveiro/.conda/envs/acra2/lib/python3.8/multiprocessing/util.py", line 416, in _flush_std_streams
    sys.stderr.flush()
FileNotFoundError: [Errno 2] No such file or directory


--------------------------------------------------------------------------------


--------------------------------------------------------------------------------
LokyProcess-4494 failed with traceback: 
--------------------------------------------------------------------------------
Traceback (most recent call last):
  File "/LUSTRE/users/rnaveiro/.conda/envs/acra2/lib/python3.8/site-packages/joblib/externals/loky/backend/popen_loky_posix.py", line 199, in <module>
    exitcode = process_obj._bootstrap()
  File "/LUSTRE/users/rnaveiro/.conda/envs/acra2/lib/python3.8/multiprocessing/process.py", line 335, in _bootstrap
    util._flush_std_streams()
  File "/LUSTRE/users/rnaveiro/.conda/envs/acra2/lib/python3.8/multiprocessing/util.py", line 416, in _flush_std_streams
    sys.stderr.flush()
FileNotFoundError: [Errno 2] No such file or directory


--------------------------------------------------------------------------------


--------------------------------------------------------------------------------
LokyProcess-4488 failed with traceback: 
--------------------------------------------------------------------------------
Traceback (most recent call last):
  File "/LUSTRE/users/rnaveiro/.conda/envs/acra2/lib/python3.8/site-packages/joblib/externals/loky/backend/popen_loky_posix.py", line 199, in <module>
    exitcode = process_obj._bootstrap()
  File "/LUSTRE/users/rnaveiro/.conda/envs/acra2/lib/python3.8/multiprocessing/process.py", line 335, in _bootstrap
    util._flush_std_streams()
  File "/LUSTRE/users/rnaveiro/.conda/envs/acra2/lib/python3.8/multiprocessing/util.py", line 416, in _flush_std_streams
    sys.stderr.flush()
FileNotFoundError: [Errno 2] No such file or directory


--------------------------------------------------------------------------------


--------------------------------------------------------------------------------
LokyProcess-4518 failed with traceback: 
--------------------------------------------------------------------------------
Traceback (most recent call last):
  File "/LUSTRE/users/rnaveiro/.conda/envs/acra2/lib/python3.8/site-packages/joblib/externals/loky/backend/popen_loky_posix.py", line 199, in <module>
    exitcode = process_obj._bootstrap()
  File "/LUSTRE/users/rnaveiro/.conda/envs/acra2/lib/python3.8/multiprocessing/process.py", line 335, in _bootstrap
    util._flush_std_streams()
  File "/LUSTRE/users/rnaveiro/.conda/envs/acra2/lib/python3.8/multiprocessing/util.py", line 416, in _flush_std_streams
    sys.stderr.flush()
FileNotFoundError: [Errno 2] No such file or directory


--------------------------------------------------------------------------------


--------------------------------------------------------------------------------
LokyProcess-4498 failed with traceback: 
--------------------------------------------------------------------------------
Traceback (most recent call last):
  File "/LUSTRE/users/rnaveiro/.conda/envs/acra2/lib/python3.8/site-packages/joblib/externals/loky/backend/popen_loky_posix.py", line 199, in <module>
    exitcode = process_obj._bootstrap()
  File "/LUSTRE/users/rnaveiro/.conda/envs/acra2/lib/python3.8/multiprocessing/process.py", line 335, in _bootstrap
    util._flush_std_streams()
  File "/LUSTRE/users/rnaveiro/.conda/envs/acra2/lib/python3.8/multiprocessing/util.py", line 416, in _flush_std_streams
    sys.stderr.flush()
FileNotFoundError: [Errno 2] No such file or directory


--------------------------------------------------------------------------------


--------------------------------------------------------------------------------
LokyProcess-4504 failed with traceback: 
--------------------------------------------------------------------------------
Traceback (most recent call last):
  File "/LUSTRE/users/rnaveiro/.conda/envs/acra2/lib/python3.8/site-packages/joblib/externals/loky/backend/popen_loky_posix.py", line 199, in <module>
    exitcode = process_obj._bootstrap()
  File "/LUSTRE/users/rnaveiro/.conda/envs/acra2/lib/python3.8/multiprocessing/process.py", line 335, in _bootstrap
    util._flush_std_streams()
  File "/LUSTRE/users/rnaveiro/.conda/envs/acra2/lib/python3.8/multiprocessing/util.py", line 416, in _flush_std_streams
    sys.stderr.flush()
FileNotFoundError: [Errno 2] No such file or directory


--------------------------------------------------------------------------------


--------------------------------------------------------------------------------
LokyProcess-4521 failed with traceback: 
--------------------------------------------------------------------------------
Traceback (most recent call last):
  File "/LUSTRE/users/rnaveiro/.conda/envs/acra2/lib/python3.8/site-packages/joblib/externals/loky/backend/popen_loky_posix.py", line 199, in <module>
    exitcode = process_obj._bootstrap()
  File "/LUSTRE/users/rnaveiro/.conda/envs/acra2/lib/python3.8/multiprocessing/process.py", line 335, in _bootstrap
    util._flush_std_streams()
  File "/LUSTRE/users/rnaveiro/.conda/envs/acra2/lib/python3.8/multiprocessing/util.py", line 416, in _flush_std_streams
    sys.stderr.flush()
FileNotFoundError: [Errno 2] No such file or directory


--------------------------------------------------------------------------------
nbACRA accuracy on tainted data var0.3 0.6541666666666667
Classifier nn
nnaccuracy on clean data 0.4583333333333333
nnaccuracy on tainted data 0.07916666666666666


--------------------------------------------------------------------------------
LokyProcess-4513 failed with traceback: 
--------------------------------------------------------------------------------
Traceback (most recent call last):
  File "/LUSTRE/users/rnaveiro/.conda/envs/acra2/lib/python3.8/site-packages/joblib/externals/loky/backend/popen_loky_posix.py", line 199, in <module>
    exitcode = process_obj._bootstrap()
  File "/LUSTRE/users/rnaveiro/.conda/envs/acra2/lib/python3.8/multiprocessing/process.py", line 335, in _bootstrap
    util._flush_std_streams()
  File "/LUSTRE/users/rnaveiro/.conda/envs/acra2/lib/python3.8/multiprocessing/util.py", line 416, in _flush_std_streams
    sys.stderr.flush()
FileNotFoundError: [Errno 2] No such file or directory


--------------------------------------------------------------------------------
nnACRA accuracy on tainted data var0 0.45416666666666666
nnACRA accuracy on tainted data var0.3 0.45416666666666666
Classifier svm
svmaccuracy on clean data 0.7291666666666666
svmaccuracy on tainted data 0.3333333333333333
svmACRA accuracy on tainted data var0 0.5291666666666667
svmACRA accuracy on tainted data var0.3 0.48333333333333334
Classifier lr
lraccuracy on clean data 0.7625
lraccuracy on tainted data 0.36666666666666664
lrACRA accuracy on tainted data var0 0.5291666666666667
lrACRA accuracy on tainted data var0.3 0.5458333333333333
Classifier rf
rfaccuracy on clean data 0.7208333333333333
rfaccuracy on tainted data 0.35
rfACRA accuracy on tainted data var0 0.7625
rfACRA accuracy on tainted data var0.3 0.775
Writing Experiment  8
Experiment:  9
Classifier nb
nbaccuracy on clean data 0.7458333333333333
nbaccuracy on tainted data 0.325
nbACRA accuracy on tainted data var0 0.5958333333333333


--------------------------------------------------------------------------------
LokyProcess-5064 failed with traceback: 
--------------------------------------------------------------------------------
Traceback (most recent call last):
  File "/LUSTRE/users/rnaveiro/.conda/envs/acra2/lib/python3.8/site-packages/joblib/externals/loky/backend/popen_loky_posix.py", line 199, in <module>
    exitcode = process_obj._bootstrap()
  File "/LUSTRE/users/rnaveiro/.conda/envs/acra2/lib/python3.8/multiprocessing/process.py", line 335, in _bootstrap
    util._flush_std_streams()
  File "/LUSTRE/users/rnaveiro/.conda/envs/acra2/lib/python3.8/multiprocessing/util.py", line 416, in _flush_std_streams
    sys.stderr.flush()
FileNotFoundError: [Errno 2] No such file or directory


--------------------------------------------------------------------------------


--------------------------------------------------------------------------------
LokyProcess-5072 failed with traceback: 
--------------------------------------------------------------------------------
Traceback (most recent call last):
  File "/LUSTRE/users/rnaveiro/.conda/envs/acra2/lib/python3.8/site-packages/joblib/externals/loky/backend/popen_loky_posix.py", line 199, in <module>
    exitcode = process_obj._bootstrap()
  File "/LUSTRE/users/rnaveiro/.conda/envs/acra2/lib/python3.8/multiprocessing/process.py", line 335, in _bootstrap
    util._flush_std_streams()
  File "/LUSTRE/users/rnaveiro/.conda/envs/acra2/lib/python3.8/multiprocessing/util.py", line 416, in _flush_std_streams
    sys.stderr.flush()
FileNotFoundError: [Errno 2] No such file or directory


--------------------------------------------------------------------------------


--------------------------------------------------------------------------------
LokyProcess-5063 failed with traceback: 
--------------------------------------------------------------------------------
Traceback (most recent call last):
  File "/LUSTRE/users/rnaveiro/.conda/envs/acra2/lib/python3.8/site-packages/joblib/externals/loky/backend/popen_loky_posix.py", line 199, in <module>
    exitcode = process_obj._bootstrap()
  File "/LUSTRE/users/rnaveiro/.conda/envs/acra2/lib/python3.8/multiprocessing/process.py", line 335, in _bootstrap
    util._flush_std_streams()
  File "/LUSTRE/users/rnaveiro/.conda/envs/acra2/lib/python3.8/multiprocessing/util.py", line 416, in _flush_std_streams
    sys.stderr.flush()
FileNotFoundError: [Errno 2] No such file or directory


--------------------------------------------------------------------------------


--------------------------------------------------------------------------------
LokyProcess-5042 failed with traceback: 
--------------------------------------------------------------------------------
Traceback (most recent call last):
  File "/LUSTRE/users/rnaveiro/.conda/envs/acra2/lib/python3.8/site-packages/joblib/externals/loky/backend/popen_loky_posix.py", line 199, in <module>
    exitcode = process_obj._bootstrap()
  File "/LUSTRE/users/rnaveiro/.conda/envs/acra2/lib/python3.8/multiprocessing/process.py", line 335, in _bootstrap
    util._flush_std_streams()
  File "/LUSTRE/users/rnaveiro/.conda/envs/acra2/lib/python3.8/multiprocessing/util.py", line 416, in _flush_std_streams
    sys.stderr.flush()
FileNotFoundError: [Errno 2] No such file or directory


--------------------------------------------------------------------------------


--------------------------------------------------------------------------------
LokyProcess-5041 failed with traceback: 
--------------------------------------------------------------------------------
Traceback (most recent call last):
  File "/LUSTRE/users/rnaveiro/.conda/envs/acra2/lib/python3.8/site-packages/joblib/externals/loky/backend/popen_loky_posix.py", line 199, in <module>
    exitcode = process_obj._bootstrap()
  File "/LUSTRE/users/rnaveiro/.conda/envs/acra2/lib/python3.8/multiprocessing/process.py", line 335, in _bootstrap
    util._flush_std_streams()
  File "/LUSTRE/users/rnaveiro/.conda/envs/acra2/lib/python3.8/multiprocessing/util.py", line 416, in _flush_std_streams
    sys.stderr.flush()
FileNotFoundError: [Errno 2] No such file or directory


--------------------------------------------------------------------------------


--------------------------------------------------------------------------------
LokyProcess-5031 failed with traceback: 
--------------------------------------------------------------------------------
Traceback (most recent call last):
  File "/LUSTRE/users/rnaveiro/.conda/envs/acra2/lib/python3.8/site-packages/joblib/externals/loky/backend/popen_loky_posix.py", line 199, in <module>
    exitcode = process_obj._bootstrap()
  File "/LUSTRE/users/rnaveiro/.conda/envs/acra2/lib/python3.8/multiprocessing/process.py", line 335, in _bootstrap
    util._flush_std_streams()
  File "/LUSTRE/users/rnaveiro/.conda/envs/acra2/lib/python3.8/multiprocessing/util.py", line 416, in _flush_std_streams
    sys.stderr.flush()
FileNotFoundError: [Errno 2] No such file or directory


--------------------------------------------------------------------------------


--------------------------------------------------------------------------------
LokyProcess-5069 failed with traceback: 
--------------------------------------------------------------------------------
Traceback (most recent call last):
  File "/LUSTRE/users/rnaveiro/.conda/envs/acra2/lib/python3.8/site-packages/joblib/externals/loky/backend/popen_loky_posix.py", line 199, in <module>
    exitcode = process_obj._bootstrap()
  File "/LUSTRE/users/rnaveiro/.conda/envs/acra2/lib/python3.8/multiprocessing/process.py", line 335, in _bootstrap
    util._flush_std_streams()
  File "/LUSTRE/users/rnaveiro/.conda/envs/acra2/lib/python3.8/multiprocessing/util.py", line 416, in _flush_std_streams
    sys.stderr.flush()
FileNotFoundError: [Errno 2] No such file or directory


--------------------------------------------------------------------------------


--------------------------------------------------------------------------------
LokyProcess-5078 failed with traceback: 
--------------------------------------------------------------------------------
Traceback (most recent call last):
  File "/LUSTRE/users/rnaveiro/.conda/envs/acra2/lib/python3.8/site-packages/joblib/externals/loky/backend/popen_loky_posix.py", line 199, in <module>
    exitcode = process_obj._bootstrap()
  File "/LUSTRE/users/rnaveiro/.conda/envs/acra2/lib/python3.8/multiprocessing/process.py", line 335, in _bootstrap
    util._flush_std_streams()
  File "/LUSTRE/users/rnaveiro/.conda/envs/acra2/lib/python3.8/multiprocessing/util.py", line 416, in _flush_std_streams
    sys.stderr.flush()
FileNotFoundError: [Errno 2] No such file or directory


--------------------------------------------------------------------------------


--------------------------------------------------------------------------------
LokyProcess-5070 failed with traceback: 
--------------------------------------------------------------------------------
Traceback (most recent call last):
  File "/LUSTRE/users/rnaveiro/.conda/envs/acra2/lib/python3.8/site-packages/joblib/externals/loky/backend/popen_loky_posix.py", line 199, in <module>
    exitcode = process_obj._bootstrap()
  File "/LUSTRE/users/rnaveiro/.conda/envs/acra2/lib/python3.8/multiprocessing/process.py", line 335, in _bootstrap
    util._flush_std_streams()
  File "/LUSTRE/users/rnaveiro/.conda/envs/acra2/lib/python3.8/multiprocessing/util.py", line 416, in _flush_std_streams
    sys.stderr.flush()
FileNotFoundError: [Errno 2] No such file or directory


--------------------------------------------------------------------------------


--------------------------------------------------------------------------------
LokyProcess-5062 failed with traceback: 
--------------------------------------------------------------------------------
Traceback (most recent call last):
  File "/LUSTRE/users/rnaveiro/.conda/envs/acra2/lib/python3.8/site-packages/joblib/externals/loky/backend/popen_loky_posix.py", line 199, in <module>
    exitcode = process_obj._bootstrap()
  File "/LUSTRE/users/rnaveiro/.conda/envs/acra2/lib/python3.8/multiprocessing/process.py", line 335, in _bootstrap
    util._flush_std_streams()
  File "/LUSTRE/users/rnaveiro/.conda/envs/acra2/lib/python3.8/multiprocessing/util.py", line 416, in _flush_std_streams
    sys.stderr.flush()
FileNotFoundError: [Errno 2] No such file or directory


--------------------------------------------------------------------------------


--------------------------------------------------------------------------------
LokyProcess-5057 failed with traceback: 
--------------------------------------------------------------------------------
Traceback (most recent call last):
  File "/LUSTRE/users/rnaveiro/.conda/envs/acra2/lib/python3.8/site-packages/joblib/externals/loky/backend/popen_loky_posix.py", line 199, in <module>
    exitcode = process_obj._bootstrap()
  File "/LUSTRE/users/rnaveiro/.conda/envs/acra2/lib/python3.8/multiprocessing/process.py", line 335, in _bootstrap
    util._flush_std_streams()
  File "/LUSTRE/users/rnaveiro/.conda/envs/acra2/lib/python3.8/multiprocessing/util.py", line 416, in _flush_std_streams
    sys.stderr.flush()
FileNotFoundError: [Errno 2] No such file or directory


--------------------------------------------------------------------------------


--------------------------------------------------------------------------------
LokyProcess-5035 failed with traceback: 
--------------------------------------------------------------------------------
Traceback (most recent call last):
  File "/LUSTRE/users/rnaveiro/.conda/envs/acra2/lib/python3.8/site-packages/joblib/externals/loky/backend/popen_loky_posix.py", line 199, in <module>
    exitcode = process_obj._bootstrap()
  File "/LUSTRE/users/rnaveiro/.conda/envs/acra2/lib/python3.8/multiprocessing/process.py", line 335, in _bootstrap
    util._flush_std_streams()
  File "/LUSTRE/users/rnaveiro/.conda/envs/acra2/lib/python3.8/multiprocessing/util.py", line 416, in _flush_std_streams
    sys.stderr.flush()
FileNotFoundError: [Errno 2] No such file or directory


--------------------------------------------------------------------------------


--------------------------------------------------------------------------------
LokyProcess-5077 failed with traceback: 
--------------------------------------------------------------------------------
Traceback (most recent call last):
  File "/LUSTRE/users/rnaveiro/.conda/envs/acra2/lib/python3.8/site-packages/joblib/externals/loky/backend/popen_loky_posix.py", line 199, in <module>
    exitcode = process_obj._bootstrap()
  File "/LUSTRE/users/rnaveiro/.conda/envs/acra2/lib/python3.8/multiprocessing/process.py", line 335, in _bootstrap
    util._flush_std_streams()
  File "/LUSTRE/users/rnaveiro/.conda/envs/acra2/lib/python3.8/multiprocessing/util.py", line 416, in _flush_std_streams
    sys.stderr.flush()
FileNotFoundError: [Errno 2] No such file or directory


--------------------------------------------------------------------------------


--------------------------------------------------------------------------------
LokyProcess-5051 failed with traceback: 
--------------------------------------------------------------------------------
Traceback (most recent call last):
  File "/LUSTRE/users/rnaveiro/.conda/envs/acra2/lib/python3.8/site-packages/joblib/externals/loky/backend/popen_loky_posix.py", line 199, in <module>
    exitcode = process_obj._bootstrap()
  File "/LUSTRE/users/rnaveiro/.conda/envs/acra2/lib/python3.8/multiprocessing/process.py", line 335, in _bootstrap
    util._flush_std_streams()
  File "/LUSTRE/users/rnaveiro/.conda/envs/acra2/lib/python3.8/multiprocessing/util.py", line 416, in _flush_std_streams
    sys.stderr.flush()
FileNotFoundError: [Errno 2] No such file or directory


--------------------------------------------------------------------------------


--------------------------------------------------------------------------------
LokyProcess-5056 failed with traceback: 
--------------------------------------------------------------------------------
Traceback (most recent call last):
  File "/LUSTRE/users/rnaveiro/.conda/envs/acra2/lib/python3.8/site-packages/joblib/externals/loky/backend/popen_loky_posix.py", line 199, in <module>
    exitcode = process_obj._bootstrap()
  File "/LUSTRE/users/rnaveiro/.conda/envs/acra2/lib/python3.8/multiprocessing/process.py", line 335, in _bootstrap
    util._flush_std_streams()
  File "/LUSTRE/users/rnaveiro/.conda/envs/acra2/lib/python3.8/multiprocessing/util.py", line 416, in _flush_std_streams
    sys.stderr.flush()
FileNotFoundError: [Errno 2] No such file or directory


--------------------------------------------------------------------------------


--------------------------------------------------------------------------------
LokyProcess-5071 failed with traceback: 
--------------------------------------------------------------------------------
Traceback (most recent call last):
  File "/LUSTRE/users/rnaveiro/.conda/envs/acra2/lib/python3.8/site-packages/joblib/externals/loky/backend/popen_loky_posix.py", line 199, in <module>
    exitcode = process_obj._bootstrap()
  File "/LUSTRE/users/rnaveiro/.conda/envs/acra2/lib/python3.8/multiprocessing/process.py", line 335, in _bootstrap
    util._flush_std_streams()
  File "/LUSTRE/users/rnaveiro/.conda/envs/acra2/lib/python3.8/multiprocessing/util.py", line 416, in _flush_std_streams
    sys.stderr.flush()
FileNotFoundError: [Errno 2] No such file or directory


--------------------------------------------------------------------------------


--------------------------------------------------------------------------------
LokyProcess-5054 failed with traceback: 
--------------------------------------------------------------------------------
Traceback (most recent call last):
  File "/LUSTRE/users/rnaveiro/.conda/envs/acra2/lib/python3.8/site-packages/joblib/externals/loky/backend/popen_loky_posix.py", line 199, in <module>
    exitcode = process_obj._bootstrap()
  File "/LUSTRE/users/rnaveiro/.conda/envs/acra2/lib/python3.8/multiprocessing/process.py", line 335, in _bootstrap
    util._flush_std_streams()
  File "/LUSTRE/users/rnaveiro/.conda/envs/acra2/lib/python3.8/multiprocessing/util.py", line 416, in _flush_std_streams
    sys.stderr.flush()
FileNotFoundError: [Errno 2] No such file or directory


--------------------------------------------------------------------------------


--------------------------------------------------------------------------------
LokyProcess-5048 failed with traceback: 
--------------------------------------------------------------------------------
Traceback (most recent call last):
  File "/LUSTRE/users/rnaveiro/.conda/envs/acra2/lib/python3.8/site-packages/joblib/externals/loky/backend/popen_loky_posix.py", line 199, in <module>
    exitcode = process_obj._bootstrap()
  File "/LUSTRE/users/rnaveiro/.conda/envs/acra2/lib/python3.8/multiprocessing/process.py", line 335, in _bootstrap
    util._flush_std_streams()
  File "/LUSTRE/users/rnaveiro/.conda/envs/acra2/lib/python3.8/multiprocessing/util.py", line 416, in _flush_std_streams
    sys.stderr.flush()
FileNotFoundError: [Errno 2] No such file or directory


--------------------------------------------------------------------------------


--------------------------------------------------------------------------------
LokyProcess-5030 failed with traceback: 
--------------------------------------------------------------------------------
Traceback (most recent call last):
  File "/LUSTRE/users/rnaveiro/.conda/envs/acra2/lib/python3.8/site-packages/joblib/externals/loky/backend/popen_loky_posix.py", line 199, in <module>
    exitcode = process_obj._bootstrap()
  File "/LUSTRE/users/rnaveiro/.conda/envs/acra2/lib/python3.8/multiprocessing/process.py", line 335, in _bootstrap
    util._flush_std_streams()
  File "/LUSTRE/users/rnaveiro/.conda/envs/acra2/lib/python3.8/multiprocessing/util.py", line 416, in _flush_std_streams
    sys.stderr.flush()
FileNotFoundError: [Errno 2] No such file or directory


--------------------------------------------------------------------------------


--------------------------------------------------------------------------------
LokyProcess-5034 failed with traceback: 
--------------------------------------------------------------------------------
Traceback (most recent call last):
  File "/LUSTRE/users/rnaveiro/.conda/envs/acra2/lib/python3.8/site-packages/joblib/externals/loky/backend/popen_loky_posix.py", line 199, in <module>
    exitcode = process_obj._bootstrap()
  File "/LUSTRE/users/rnaveiro/.conda/envs/acra2/lib/python3.8/multiprocessing/process.py", line 335, in _bootstrap
    util._flush_std_streams()
  File "/LUSTRE/users/rnaveiro/.conda/envs/acra2/lib/python3.8/multiprocessing/util.py", line 416, in _flush_std_streams
    sys.stderr.flush()
FileNotFoundError: [Errno 2] No such file or directory


--------------------------------------------------------------------------------


--------------------------------------------------------------------------------
LokyProcess-5052 failed with traceback: 
--------------------------------------------------------------------------------
Traceback (most recent call last):
  File "/LUSTRE/users/rnaveiro/.conda/envs/acra2/lib/python3.8/site-packages/joblib/externals/loky/backend/popen_loky_posix.py", line 199, in <module>
    exitcode = process_obj._bootstrap()
  File "/LUSTRE/users/rnaveiro/.conda/envs/acra2/lib/python3.8/multiprocessing/process.py", line 335, in _bootstrap
    util._flush_std_streams()
  File "/LUSTRE/users/rnaveiro/.conda/envs/acra2/lib/python3.8/multiprocessing/util.py", line 416, in _flush_std_streams
    sys.stderr.flush()
FileNotFoundError: [Errno 2] No such file or directory


--------------------------------------------------------------------------------


--------------------------------------------------------------------------------
LokyProcess-5073 failed with traceback: 
--------------------------------------------------------------------------------
Traceback (most recent call last):
  File "/LUSTRE/users/rnaveiro/.conda/envs/acra2/lib/python3.8/site-packages/joblib/externals/loky/backend/popen_loky_posix.py", line 199, in <module>
    exitcode = process_obj._bootstrap()
  File "/LUSTRE/users/rnaveiro/.conda/envs/acra2/lib/python3.8/multiprocessing/process.py", line 335, in _bootstrap
    util._flush_std_streams()
  File "/LUSTRE/users/rnaveiro/.conda/envs/acra2/lib/python3.8/multiprocessing/util.py", line 416, in _flush_std_streams
    sys.stderr.flush()
FileNotFoundError: [Errno 2] No such file or directory


--------------------------------------------------------------------------------


--------------------------------------------------------------------------------
LokyProcess-5044 failed with traceback: 
--------------------------------------------------------------------------------
Traceback (most recent call last):
  File "/LUSTRE/users/rnaveiro/.conda/envs/acra2/lib/python3.8/site-packages/joblib/externals/loky/backend/popen_loky_posix.py", line 199, in <module>
    exitcode = process_obj._bootstrap()
  File "/LUSTRE/users/rnaveiro/.conda/envs/acra2/lib/python3.8/multiprocessing/process.py", line 335, in _bootstrap
    util._flush_std_streams()
  File "/LUSTRE/users/rnaveiro/.conda/envs/acra2/lib/python3.8/multiprocessing/util.py", line 416, in _flush_std_streams
    sys.stderr.flush()
FileNotFoundError: [Errno 2] No such file or directory


--------------------------------------------------------------------------------


--------------------------------------------------------------------------------
LokyProcess-5011 failed with traceback: 
--------------------------------------------------------------------------------
Traceback (most recent call last):
  File "/LUSTRE/users/rnaveiro/.conda/envs/acra2/lib/python3.8/site-packages/joblib/externals/loky/backend/popen_loky_posix.py", line 199, in <module>
    exitcode = process_obj._bootstrap()
  File "/LUSTRE/users/rnaveiro/.conda/envs/acra2/lib/python3.8/multiprocessing/process.py", line 335, in _bootstrap
    util._flush_std_streams()
  File "/LUSTRE/users/rnaveiro/.conda/envs/acra2/lib/python3.8/multiprocessing/util.py", line 416, in _flush_std_streams
    sys.stderr.flush()
FileNotFoundError: [Errno 2] No such file or directory


--------------------------------------------------------------------------------


--------------------------------------------------------------------------------
LokyProcess-5046 failed with traceback: 
--------------------------------------------------------------------------------
Traceback (most recent call last):
  File "/LUSTRE/users/rnaveiro/.conda/envs/acra2/lib/python3.8/site-packages/joblib/externals/loky/backend/popen_loky_posix.py", line 199, in <module>
    exitcode = process_obj._bootstrap()
  File "/LUSTRE/users/rnaveiro/.conda/envs/acra2/lib/python3.8/multiprocessing/process.py", line 335, in _bootstrap
    util._flush_std_streams()
  File "/LUSTRE/users/rnaveiro/.conda/envs/acra2/lib/python3.8/multiprocessing/util.py", line 416, in _flush_std_streams
    sys.stderr.flush()
FileNotFoundError: [Errno 2] No such file or directory


--------------------------------------------------------------------------------


--------------------------------------------------------------------------------
LokyProcess-5036 failed with traceback: 
--------------------------------------------------------------------------------
Traceback (most recent call last):
  File "/LUSTRE/users/rnaveiro/.conda/envs/acra2/lib/python3.8/site-packages/joblib/externals/loky/backend/popen_loky_posix.py", line 199, in <module>
    exitcode = process_obj._bootstrap()
  File "/LUSTRE/users/rnaveiro/.conda/envs/acra2/lib/python3.8/multiprocessing/process.py", line 335, in _bootstrap
    util._flush_std_streams()
  File "/LUSTRE/users/rnaveiro/.conda/envs/acra2/lib/python3.8/multiprocessing/util.py", line 416, in _flush_std_streams
    sys.stderr.flush()
FileNotFoundError: [Errno 2] No such file or directory


--------------------------------------------------------------------------------


--------------------------------------------------------------------------------
LokyProcess-5040 failed with traceback: 
--------------------------------------------------------------------------------
Traceback (most recent call last):
  File "/LUSTRE/users/rnaveiro/.conda/envs/acra2/lib/python3.8/site-packages/joblib/externals/loky/backend/popen_loky_posix.py", line 199, in <module>
    exitcode = process_obj._bootstrap()
  File "/LUSTRE/users/rnaveiro/.conda/envs/acra2/lib/python3.8/multiprocessing/process.py", line 335, in _bootstrap
    util._flush_std_streams()
  File "/LUSTRE/users/rnaveiro/.conda/envs/acra2/lib/python3.8/multiprocessing/util.py", line 416, in _flush_std_streams
    sys.stderr.flush()
FileNotFoundError: [Errno 2] No such file or directory


--------------------------------------------------------------------------------


--------------------------------------------------------------------------------
LokyProcess-5058 failed with traceback: 
--------------------------------------------------------------------------------
Traceback (most recent call last):
  File "/LUSTRE/users/rnaveiro/.conda/envs/acra2/lib/python3.8/site-packages/joblib/externals/loky/backend/popen_loky_posix.py", line 199, in <module>
    exitcode = process_obj._bootstrap()
  File "/LUSTRE/users/rnaveiro/.conda/envs/acra2/lib/python3.8/multiprocessing/process.py", line 335, in _bootstrap
    util._flush_std_streams()
  File "/LUSTRE/users/rnaveiro/.conda/envs/acra2/lib/python3.8/multiprocessing/util.py", line 416, in _flush_std_streams
    sys.stderr.flush()
FileNotFoundError: [Errno 2] No such file or directory


--------------------------------------------------------------------------------


--------------------------------------------------------------------------------
LokyProcess-5038 failed with traceback: 
--------------------------------------------------------------------------------
Traceback (most recent call last):
  File "/LUSTRE/users/rnaveiro/.conda/envs/acra2/lib/python3.8/site-packages/joblib/externals/loky/backend/popen_loky_posix.py", line 199, in <module>
    exitcode = process_obj._bootstrap()
  File "/LUSTRE/users/rnaveiro/.conda/envs/acra2/lib/python3.8/multiprocessing/process.py", line 335, in _bootstrap
    util._flush_std_streams()
  File "/LUSTRE/users/rnaveiro/.conda/envs/acra2/lib/python3.8/multiprocessing/util.py", line 416, in _flush_std_streams
    sys.stderr.flush()
FileNotFoundError: [Errno 2] No such file or directory


--------------------------------------------------------------------------------


--------------------------------------------------------------------------------
LokyProcess-5033 failed with traceback: 
--------------------------------------------------------------------------------
Traceback (most recent call last):
  File "/LUSTRE/users/rnaveiro/.conda/envs/acra2/lib/python3.8/site-packages/joblib/externals/loky/backend/popen_loky_posix.py", line 199, in <module>
    exitcode = process_obj._bootstrap()
  File "/LUSTRE/users/rnaveiro/.conda/envs/acra2/lib/python3.8/multiprocessing/process.py", line 335, in _bootstrap
    util._flush_std_streams()
  File "/LUSTRE/users/rnaveiro/.conda/envs/acra2/lib/python3.8/multiprocessing/util.py", line 416, in _flush_std_streams
    sys.stderr.flush()
FileNotFoundError: [Errno 2] No such file or directory


--------------------------------------------------------------------------------


--------------------------------------------------------------------------------
LokyProcess-5067 failed with traceback: 
--------------------------------------------------------------------------------
Traceback (most recent call last):
  File "/LUSTRE/users/rnaveiro/.conda/envs/acra2/lib/python3.8/site-packages/joblib/externals/loky/backend/popen_loky_posix.py", line 199, in <module>
    exitcode = process_obj._bootstrap()
  File "/LUSTRE/users/rnaveiro/.conda/envs/acra2/lib/python3.8/multiprocessing/process.py", line 335, in _bootstrap
    util._flush_std_streams()
  File "/LUSTRE/users/rnaveiro/.conda/envs/acra2/lib/python3.8/multiprocessing/util.py", line 416, in _flush_std_streams
    sys.stderr.flush()
FileNotFoundError: [Errno 2] No such file or directory


--------------------------------------------------------------------------------


--------------------------------------------------------------------------------
LokyProcess-5050 failed with traceback: 
--------------------------------------------------------------------------------
Traceback (most recent call last):
  File "/LUSTRE/users/rnaveiro/.conda/envs/acra2/lib/python3.8/site-packages/joblib/externals/loky/backend/popen_loky_posix.py", line 199, in <module>
    exitcode = process_obj._bootstrap()
  File "/LUSTRE/users/rnaveiro/.conda/envs/acra2/lib/python3.8/multiprocessing/process.py", line 335, in _bootstrap
    util._flush_std_streams()
  File "/LUSTRE/users/rnaveiro/.conda/envs/acra2/lib/python3.8/multiprocessing/util.py", line 416, in _flush_std_streams
    sys.stderr.flush()
FileNotFoundError: [Errno 2] No such file or directory


--------------------------------------------------------------------------------


--------------------------------------------------------------------------------
LokyProcess-5053 failed with traceback: 
--------------------------------------------------------------------------------
Traceback (most recent call last):
  File "/LUSTRE/users/rnaveiro/.conda/envs/acra2/lib/python3.8/site-packages/joblib/externals/loky/backend/popen_loky_posix.py", line 199, in <module>
    exitcode = process_obj._bootstrap()
  File "/LUSTRE/users/rnaveiro/.conda/envs/acra2/lib/python3.8/multiprocessing/process.py", line 335, in _bootstrap
    util._flush_std_streams()
  File "/LUSTRE/users/rnaveiro/.conda/envs/acra2/lib/python3.8/multiprocessing/util.py", line 416, in _flush_std_streams
    sys.stderr.flush()
FileNotFoundError: [Errno 2] No such file or directory


--------------------------------------------------------------------------------


--------------------------------------------------------------------------------
LokyProcess-5076 failed with traceback: 
--------------------------------------------------------------------------------
Traceback (most recent call last):
  File "/LUSTRE/users/rnaveiro/.conda/envs/acra2/lib/python3.8/site-packages/joblib/externals/loky/backend/popen_loky_posix.py", line 199, in <module>
    exitcode = process_obj._bootstrap()
  File "/LUSTRE/users/rnaveiro/.conda/envs/acra2/lib/python3.8/multiprocessing/process.py", line 335, in _bootstrap
    util._flush_std_streams()
  File "/LUSTRE/users/rnaveiro/.conda/envs/acra2/lib/python3.8/multiprocessing/util.py", line 416, in _flush_std_streams
    sys.stderr.flush()
FileNotFoundError: [Errno 2] No such file or directory


--------------------------------------------------------------------------------


--------------------------------------------------------------------------------
LokyProcess-5037 failed with traceback: 
--------------------------------------------------------------------------------
Traceback (most recent call last):
  File "/LUSTRE/users/rnaveiro/.conda/envs/acra2/lib/python3.8/site-packages/joblib/externals/loky/backend/popen_loky_posix.py", line 199, in <module>
    exitcode = process_obj._bootstrap()
  File "/LUSTRE/users/rnaveiro/.conda/envs/acra2/lib/python3.8/multiprocessing/process.py", line 335, in _bootstrap
    util._flush_std_streams()
  File "/LUSTRE/users/rnaveiro/.conda/envs/acra2/lib/python3.8/multiprocessing/util.py", line 416, in _flush_std_streams
    sys.stderr.flush()
FileNotFoundError: [Errno 2] No such file or directory


--------------------------------------------------------------------------------


--------------------------------------------------------------------------------
LokyProcess-5060 failed with traceback: 
--------------------------------------------------------------------------------
Traceback (most recent call last):
  File "/LUSTRE/users/rnaveiro/.conda/envs/acra2/lib/python3.8/site-packages/joblib/externals/loky/backend/popen_loky_posix.py", line 199, in <module>
    exitcode = process_obj._bootstrap()
  File "/LUSTRE/users/rnaveiro/.conda/envs/acra2/lib/python3.8/multiprocessing/process.py", line 335, in _bootstrap
    util._flush_std_streams()
  File "/LUSTRE/users/rnaveiro/.conda/envs/acra2/lib/python3.8/multiprocessing/util.py", line 416, in _flush_std_streams
    sys.stderr.flush()
FileNotFoundError: [Errno 2] No such file or directory


--------------------------------------------------------------------------------


--------------------------------------------------------------------------------
LokyProcess-5045 failed with traceback: 
--------------------------------------------------------------------------------
Traceback (most recent call last):
  File "/LUSTRE/users/rnaveiro/.conda/envs/acra2/lib/python3.8/site-packages/joblib/externals/loky/backend/popen_loky_posix.py", line 199, in <module>
    exitcode = process_obj._bootstrap()
  File "/LUSTRE/users/rnaveiro/.conda/envs/acra2/lib/python3.8/multiprocessing/process.py", line 335, in _bootstrap
    util._flush_std_streams()
  File "/LUSTRE/users/rnaveiro/.conda/envs/acra2/lib/python3.8/multiprocessing/util.py", line 416, in _flush_std_streams
    sys.stderr.flush()
FileNotFoundError: [Errno 2] No such file or directory


--------------------------------------------------------------------------------


--------------------------------------------------------------------------------
LokyProcess-5066 failed with traceback: 
--------------------------------------------------------------------------------
Traceback (most recent call last):
  File "/LUSTRE/users/rnaveiro/.conda/envs/acra2/lib/python3.8/site-packages/joblib/externals/loky/backend/popen_loky_posix.py", line 199, in <module>
    exitcode = process_obj._bootstrap()
  File "/LUSTRE/users/rnaveiro/.conda/envs/acra2/lib/python3.8/multiprocessing/process.py", line 335, in _bootstrap
    util._flush_std_streams()
  File "/LUSTRE/users/rnaveiro/.conda/envs/acra2/lib/python3.8/multiprocessing/util.py", line 416, in _flush_std_streams
    sys.stderr.flush()
FileNotFoundError: [Errno 2] No such file or directory


--------------------------------------------------------------------------------


--------------------------------------------------------------------------------
LokyProcess-5032 failed with traceback: 
--------------------------------------------------------------------------------
Traceback (most recent call last):
  File "/LUSTRE/users/rnaveiro/.conda/envs/acra2/lib/python3.8/site-packages/joblib/externals/loky/backend/popen_loky_posix.py", line 199, in <module>
    exitcode = process_obj._bootstrap()
  File "/LUSTRE/users/rnaveiro/.conda/envs/acra2/lib/python3.8/multiprocessing/process.py", line 335, in _bootstrap
    util._flush_std_streams()
  File "/LUSTRE/users/rnaveiro/.conda/envs/acra2/lib/python3.8/multiprocessing/util.py", line 416, in _flush_std_streams
    sys.stderr.flush()
FileNotFoundError: [Errno 2] No such file or directory


--------------------------------------------------------------------------------


--------------------------------------------------------------------------------
LokyProcess-5065 failed with traceback: 
--------------------------------------------------------------------------------
Traceback (most recent call last):
  File "/LUSTRE/users/rnaveiro/.conda/envs/acra2/lib/python3.8/site-packages/joblib/externals/loky/backend/popen_loky_posix.py", line 199, in <module>
    exitcode = process_obj._bootstrap()
  File "/LUSTRE/users/rnaveiro/.conda/envs/acra2/lib/python3.8/multiprocessing/process.py", line 335, in _bootstrap
    util._flush_std_streams()
  File "/LUSTRE/users/rnaveiro/.conda/envs/acra2/lib/python3.8/multiprocessing/util.py", line 416, in _flush_std_streams
    sys.stderr.flush()
FileNotFoundError: [Errno 2] No such file or directory


--------------------------------------------------------------------------------


--------------------------------------------------------------------------------
LokyProcess-5049 failed with traceback: 
--------------------------------------------------------------------------------
Traceback (most recent call last):
  File "/LUSTRE/users/rnaveiro/.conda/envs/acra2/lib/python3.8/site-packages/joblib/externals/loky/backend/popen_loky_posix.py", line 199, in <module>
    exitcode = process_obj._bootstrap()
  File "/LUSTRE/users/rnaveiro/.conda/envs/acra2/lib/python3.8/multiprocessing/process.py", line 335, in _bootstrap
    util._flush_std_streams()
  File "/LUSTRE/users/rnaveiro/.conda/envs/acra2/lib/python3.8/multiprocessing/util.py", line 416, in _flush_std_streams
    sys.stderr.flush()
FileNotFoundError: [Errno 2] No such file or directory


--------------------------------------------------------------------------------


--------------------------------------------------------------------------------
LokyProcess-5068 failed with traceback: 
--------------------------------------------------------------------------------
Traceback (most recent call last):
  File "/LUSTRE/users/rnaveiro/.conda/envs/acra2/lib/python3.8/site-packages/joblib/externals/loky/backend/popen_loky_posix.py", line 199, in <module>
    exitcode = process_obj._bootstrap()
  File "/LUSTRE/users/rnaveiro/.conda/envs/acra2/lib/python3.8/multiprocessing/process.py", line 335, in _bootstrap
    util._flush_std_streams()
  File "/LUSTRE/users/rnaveiro/.conda/envs/acra2/lib/python3.8/multiprocessing/util.py", line 416, in _flush_std_streams
    sys.stderr.flush()
FileNotFoundError: [Errno 2] No such file or directory


--------------------------------------------------------------------------------


--------------------------------------------------------------------------------
LokyProcess-5043 failed with traceback: 
--------------------------------------------------------------------------------
Traceback (most recent call last):
  File "/LUSTRE/users/rnaveiro/.conda/envs/acra2/lib/python3.8/site-packages/joblib/externals/loky/backend/popen_loky_posix.py", line 199, in <module>
    exitcode = process_obj._bootstrap()
  File "/LUSTRE/users/rnaveiro/.conda/envs/acra2/lib/python3.8/multiprocessing/process.py", line 335, in _bootstrap
    util._flush_std_streams()
  File "/LUSTRE/users/rnaveiro/.conda/envs/acra2/lib/python3.8/multiprocessing/util.py", line 416, in _flush_std_streams
    sys.stderr.flush()
FileNotFoundError: [Errno 2] No such file or directory


--------------------------------------------------------------------------------


--------------------------------------------------------------------------------
LokyProcess-5074 failed with traceback: 
--------------------------------------------------------------------------------
Traceback (most recent call last):
  File "/LUSTRE/users/rnaveiro/.conda/envs/acra2/lib/python3.8/site-packages/joblib/externals/loky/backend/popen_loky_posix.py", line 199, in <module>
    exitcode = process_obj._bootstrap()
  File "/LUSTRE/users/rnaveiro/.conda/envs/acra2/lib/python3.8/multiprocessing/process.py", line 335, in _bootstrap
    util._flush_std_streams()
  File "/LUSTRE/users/rnaveiro/.conda/envs/acra2/lib/python3.8/multiprocessing/util.py", line 416, in _flush_std_streams
    sys.stderr.flush()
FileNotFoundError: [Errno 2] No such file or directory


--------------------------------------------------------------------------------


--------------------------------------------------------------------------------
LokyProcess-5055 failed with traceback: 
--------------------------------------------------------------------------------
Traceback (most recent call last):
  File "/LUSTRE/users/rnaveiro/.conda/envs/acra2/lib/python3.8/site-packages/joblib/externals/loky/backend/popen_loky_posix.py", line 199, in <module>
    exitcode = process_obj._bootstrap()
  File "/LUSTRE/users/rnaveiro/.conda/envs/acra2/lib/python3.8/multiprocessing/process.py", line 335, in _bootstrap
    util._flush_std_streams()
  File "/LUSTRE/users/rnaveiro/.conda/envs/acra2/lib/python3.8/multiprocessing/util.py", line 416, in _flush_std_streams
    sys.stderr.flush()
FileNotFoundError: [Errno 2] No such file or directory


--------------------------------------------------------------------------------


--------------------------------------------------------------------------------
LokyProcess-5039 failed with traceback: 
--------------------------------------------------------------------------------
Traceback (most recent call last):
  File "/LUSTRE/users/rnaveiro/.conda/envs/acra2/lib/python3.8/site-packages/joblib/externals/loky/backend/popen_loky_posix.py", line 199, in <module>
    exitcode = process_obj._bootstrap()
  File "/LUSTRE/users/rnaveiro/.conda/envs/acra2/lib/python3.8/multiprocessing/process.py", line 335, in _bootstrap
    util._flush_std_streams()
  File "/LUSTRE/users/rnaveiro/.conda/envs/acra2/lib/python3.8/multiprocessing/util.py", line 416, in _flush_std_streams
    sys.stderr.flush()
FileNotFoundError: [Errno 2] No such file or directory


--------------------------------------------------------------------------------


--------------------------------------------------------------------------------
LokyProcess-5059 failed with traceback: 
--------------------------------------------------------------------------------
Traceback (most recent call last):
  File "/LUSTRE/users/rnaveiro/.conda/envs/acra2/lib/python3.8/site-packages/joblib/externals/loky/backend/popen_loky_posix.py", line 199, in <module>
    exitcode = process_obj._bootstrap()
  File "/LUSTRE/users/rnaveiro/.conda/envs/acra2/lib/python3.8/multiprocessing/process.py", line 335, in _bootstrap
    util._flush_std_streams()
  File "/LUSTRE/users/rnaveiro/.conda/envs/acra2/lib/python3.8/multiprocessing/util.py", line 416, in _flush_std_streams
    sys.stderr.flush()
FileNotFoundError: [Errno 2] No such file or directory


--------------------------------------------------------------------------------


--------------------------------------------------------------------------------
LokyProcess-5047 failed with traceback: 
--------------------------------------------------------------------------------
Traceback (most recent call last):
  File "/LUSTRE/users/rnaveiro/.conda/envs/acra2/lib/python3.8/site-packages/joblib/externals/loky/backend/popen_loky_posix.py", line 199, in <module>
    exitcode = process_obj._bootstrap()
  File "/LUSTRE/users/rnaveiro/.conda/envs/acra2/lib/python3.8/multiprocessing/process.py", line 335, in _bootstrap
    util._flush_std_streams()
  File "/LUSTRE/users/rnaveiro/.conda/envs/acra2/lib/python3.8/multiprocessing/util.py", line 416, in _flush_std_streams
    sys.stderr.flush()
FileNotFoundError: [Errno 2] No such file or directory


--------------------------------------------------------------------------------
nbACRA accuracy on tainted data var0.3 0.6125
Classifier nn
nnaccuracy on clean data 0.5541666666666667
nnaccuracy on tainted data 0.3958333333333333


--------------------------------------------------------------------------------
LokyProcess-5075 failed with traceback: 
--------------------------------------------------------------------------------
Traceback (most recent call last):
  File "/LUSTRE/users/rnaveiro/.conda/envs/acra2/lib/python3.8/site-packages/joblib/externals/loky/backend/popen_loky_posix.py", line 199, in <module>
    exitcode = process_obj._bootstrap()
  File "/LUSTRE/users/rnaveiro/.conda/envs/acra2/lib/python3.8/multiprocessing/process.py", line 335, in _bootstrap
    util._flush_std_streams()
  File "/LUSTRE/users/rnaveiro/.conda/envs/acra2/lib/python3.8/multiprocessing/util.py", line 416, in _flush_std_streams
    sys.stderr.flush()
FileNotFoundError: [Errno 2] No such file or directory


--------------------------------------------------------------------------------
nnACRA accuracy on tainted data var0 0.5
nnACRA accuracy on tainted data var0.3 0.5916666666666667
Classifier svm
svmaccuracy on clean data 0.6833333333333333
svmaccuracy on tainted data 0.2708333333333333
svmACRA accuracy on tainted data var0 0.5125
svmACRA accuracy on tainted data var0.3 0.4708333333333333
Classifier lr
lraccuracy on clean data 0.7125
lraccuracy on tainted data 0.3125
lrACRA accuracy on tainted data var0 0.48333333333333334
lrACRA accuracy on tainted data var0.3 0.49166666666666664
Classifier rf
rfaccuracy on clean data 0.7208333333333333
rfaccuracy on tainted data 0.3
rfACRA accuracy on tainted data var0 0.7291666666666666
rfACRA accuracy on tainted data var0.3 0.6958333333333333
Writing Experiment  9
