Number of bads in sentiment bad
68
Number of bads in sentiment good
3
Experiment:  0
Classifier nb
nbaccuracy on clean data 0.6875
nbaccuracy on tainted data 0.2875
nbACRA accuracy on tainted data var0 0.5833333333333334
nbACRA accuracy on tainted data var0.5 0.6083333333333333
Classifier nn
nnaccuracy on clean data 0.7416666666666667
nnaccuracy on tainted data 0.2916666666666667
nnACRA accuracy on tainted data var0 0.55
nnACRA accuracy on tainted data var0.5 0.6083333333333333
Classifier svm
svmaccuracy on clean data 0.6875
svmaccuracy on tainted data 0.24166666666666667
svmACRA accuracy on tainted data var0 0.4583333333333333
svmACRA accuracy on tainted data var0.5 0.4708333333333333
Classifier lr
lraccuracy on clean data 0.7416666666666667
lraccuracy on tainted data 0.2833333333333333
lrACRA accuracy on tainted data var0 0.45416666666666666
lrACRA accuracy on tainted data var0.5 0.4791666666666667
Classifier rf
rfaccuracy on clean data 0.6916666666666667
rfaccuracy on tainted data 0.26666666666666666
rfACRA accuracy on tainted data var0 0.675
rfACRA accuracy on tainted data var0.5 0.6166666666666667
Writing Experiment  0
Experiment:  1
Classifier nb
nbaccuracy on clean data 0.7333333333333333
nbaccuracy on tainted data 0.3541666666666667
nbACRA accuracy on tainted data var0 0.6083333333333333
nbACRA accuracy on tainted data var0.5 0.6125
Classifier nn
nnaccuracy on clean data 0.5916666666666667
nnaccuracy on tainted data 0.4375
nnACRA accuracy on tainted data var0 0.6833333333333333
nnACRA accuracy on tainted data var0.5 0.7416666666666667
Classifier svm
svmaccuracy on clean data 0.7416666666666667
svmaccuracy on tainted data 0.31666666666666665
svmACRA accuracy on tainted data var0 0.49166666666666664
svmACRA accuracy on tainted data var0.5 0.4666666666666667
Classifier lr
lraccuracy on clean data 0.7458333333333333
lraccuracy on tainted data 0.3458333333333333
lrACRA accuracy on tainted data var0 0.5
lrACRA accuracy on tainted data var0.5 0.5041666666666667
Classifier rf
rfaccuracy on clean data 0.7041666666666667
rfaccuracy on tainted data 0.325
rfACRA accuracy on tainted data var0 0.7333333333333333
rfACRA accuracy on tainted data var0.5 0.6958333333333333
Writing Experiment  1
Experiment:  2
Classifier nb
nbaccuracy on clean data 0.7666666666666667
nbaccuracy on tainted data 0.3541666666666667
nbACRA accuracy on tainted data var0 0.7583333333333333
nbACRA accuracy on tainted data var0.5 0.7625
Classifier nn
nnaccuracy on clean data 0.7583333333333333
nnaccuracy on tainted data 0.3375
nnACRA accuracy on tainted data var0 0.6333333333333333
nnACRA accuracy on tainted data var0.5 0.6416666666666667
Classifier svm
svmaccuracy on clean data 0.7458333333333333
svmaccuracy on tainted data 0.30833333333333335
svmACRA accuracy on tainted data var0 0.525
svmACRA accuracy on tainted data var0.5 0.5416666666666666
Classifier lr
lraccuracy on clean data 0.7416666666666667
lraccuracy on tainted data 0.30416666666666664
lrACRA accuracy on tainted data var0 0.4791666666666667
lrACRA accuracy on tainted data var0.5 0.4875
Classifier rf
rfaccuracy on clean data 0.7375
rfaccuracy on tainted data 0.30833333333333335
rfACRA accuracy on tainted data var0 0.7208333333333333
rfACRA accuracy on tainted data var0.5 0.7333333333333333
Writing Experiment  2
Experiment:  3
Classifier nb
nbaccuracy on clean data 0.7208333333333333
nbaccuracy on tainted data 0.32083333333333336
nbACRA accuracy on tainted data var0 0.6041666666666666
nbACRA accuracy on tainted data var0.5 0.625
Classifier nn
nnaccuracy on clean data 0.6958333333333333
nnaccuracy on tainted data 0.32916666666666666
nnACRA accuracy on tainted data var0 0.7208333333333333
nnACRA accuracy on tainted data var0.5 0.7375
Classifier svm
svmaccuracy on clean data 0.75
svmaccuracy on tainted data 0.3125
svmACRA accuracy on tainted data var0 0.4875
svmACRA accuracy on tainted data var0.5 0.4791666666666667
Classifier lr
lraccuracy on clean data 0.725
lraccuracy on tainted data 0.30416666666666664
lrACRA accuracy on tainted data var0 0.5041666666666667
lrACRA accuracy on tainted data var0.5 0.5
Classifier rf
rfaccuracy on clean data 0.75
rfaccuracy on tainted data 0.31666666666666665
rfACRA accuracy on tainted data var0 0.6916666666666667
rfACRA accuracy on tainted data var0.5 0.6583333333333333
Writing Experiment  3
Experiment:  4
Classifier nb
nbaccuracy on clean data 0.6875
nbaccuracy on tainted data 0.3
nbACRA accuracy on tainted data var0 0.5583333333333333
nbACRA accuracy on tainted data var0.5 0.5791666666666667
Classifier nn
nnaccuracy on clean data 0.5125
nnaccuracy on tainted data 0.5125
nnACRA accuracy on tainted data var0 0.5125
nnACRA accuracy on tainted data var0.5 0.5125
Classifier svm
svmaccuracy on clean data 0.7083333333333334
svmaccuracy on tainted data 0.275
svmACRA accuracy on tainted data var0 0.4875
svmACRA accuracy on tainted data var0.5 0.4666666666666667
Classifier lr
lraccuracy on clean data 0.725
lraccuracy on tainted data 0.2916666666666667
lrACRA accuracy on tainted data var0 0.48333333333333334
lrACRA accuracy on tainted data var0.5 0.5
Classifier rf
rfaccuracy on clean data 0.675
rfaccuracy on tainted data 0.275
rfACRA accuracy on tainted data var0 0.7208333333333333
rfACRA accuracy on tainted data var0.5 0.6916666666666667
Writing Experiment  4
Experiment:  5
Classifier nb
nbaccuracy on clean data 0.725
nbaccuracy on tainted data 0.3458333333333333
nbACRA accuracy on tainted data var0 0.6416666666666667
nbACRA accuracy on tainted data var0.5 0.6708333333333333
Classifier nn
nnaccuracy on clean data 0.575
nnaccuracy on tainted data 0.4666666666666667
nnACRA accuracy on tainted data var0 0.4375
nnACRA accuracy on tainted data var0.5 0.475
Classifier svm
svmaccuracy on clean data 0.7208333333333333
svmaccuracy on tainted data 0.32083333333333336
svmACRA accuracy on tainted data var0 0.45
svmACRA accuracy on tainted data var0.5 0.4583333333333333
Classifier lr
lraccuracy on clean data 0.7291666666666666
lraccuracy on tainted data 0.3333333333333333
lrACRA accuracy on tainted data var0 0.525
lrACRA accuracy on tainted data var0.5 0.5458333333333333
Classifier rf
rfaccuracy on clean data 0.7291666666666666
rfaccuracy on tainted data 0.35833333333333334
rfACRA accuracy on tainted data var0 0.7625
rfACRA accuracy on tainted data var0.5 0.7666666666666667
Writing Experiment  5
Experiment:  6
Classifier nb
nbaccuracy on clean data 0.6833333333333333
nbaccuracy on tainted data 0.3125
nbACRA accuracy on tainted data var0 0.6208333333333333
nbACRA accuracy on tainted data var0.5 0.6583333333333333
Classifier nn
nnaccuracy on clean data 0.7166666666666667
nnaccuracy on tainted data 0.3458333333333333
nnACRA accuracy on tainted data var0 0.6916666666666667
nnACRA accuracy on tainted data var0.5 0.7208333333333333
Classifier svm
svmaccuracy on clean data 0.6791666666666667
svmaccuracy on tainted data 0.3
svmACRA accuracy on tainted data var0 0.5541666666666667
svmACRA accuracy on tainted data var0.5 0.5083333333333333
Classifier lr
lraccuracy on clean data 0.7
lraccuracy on tainted data 0.32083333333333336
lrACRA accuracy on tainted data var0 0.5375
lrACRA accuracy on tainted data var0.5 0.5541666666666667
Classifier rf
rfaccuracy on clean data 0.7
rfaccuracy on tainted data 0.32083333333333336
rfACRA accuracy on tainted data var0 0.775
rfACRA accuracy on tainted data var0.5 0.7541666666666667
Writing Experiment  6
Experiment:  7
Classifier nb
nbaccuracy on clean data 0.6916666666666667
nbaccuracy on tainted data 0.32916666666666666
nbACRA accuracy on tainted data var0 0.8125
nbACRA accuracy on tainted data var0.5 0.825
Classifier nn
nnaccuracy on clean data 0.525
nnaccuracy on tainted data 0.3625
nnACRA accuracy on tainted data var0 0.5791666666666667
nnACRA accuracy on tainted data var0.5 0.6791666666666667
Classifier svm
svmaccuracy on clean data 0.725
svmaccuracy on tainted data 0.32916666666666666
svmACRA accuracy on tainted data var0 0.48333333333333334
svmACRA accuracy on tainted data var0.5 0.42083333333333334
Classifier lr
lraccuracy on clean data 0.725
lraccuracy on tainted data 0.32916666666666666
lrACRA accuracy on tainted data var0 0.5208333333333334
lrACRA accuracy on tainted data var0.5 0.5125
Classifier rf
rfaccuracy on clean data 0.7208333333333333
rfaccuracy on tainted data 0.32916666666666666
rfACRA accuracy on tainted data var0 0.6541666666666667
rfACRA accuracy on tainted data var0.5 0.675
Writing Experiment  7
Experiment:  8
Classifier nb
nbaccuracy on clean data 0.75
nbaccuracy on tainted data 0.3375
nbACRA accuracy on tainted data var0 0.6125


--------------------------------------------------------------------------------
LokyProcess-4521 failed with traceback: 
--------------------------------------------------------------------------------
Traceback (most recent call last):
  File "/LUSTRE/users/rnaveiro/.conda/envs/acra2/lib/python3.8/site-packages/joblib/externals/loky/backend/popen_loky_posix.py", line 199, in <module>
    exitcode = process_obj._bootstrap()
  File "/LUSTRE/users/rnaveiro/.conda/envs/acra2/lib/python3.8/multiprocessing/process.py", line 335, in _bootstrap
    util._flush_std_streams()
  File "/LUSTRE/users/rnaveiro/.conda/envs/acra2/lib/python3.8/multiprocessing/util.py", line 416, in _flush_std_streams
    sys.stderr.flush()
FileNotFoundError: [Errno 2] No such file or directory


--------------------------------------------------------------------------------


--------------------------------------------------------------------------------
LokyProcess-4517 failed with traceback: 
--------------------------------------------------------------------------------
Traceback (most recent call last):
  File "/LUSTRE/users/rnaveiro/.conda/envs/acra2/lib/python3.8/site-packages/joblib/externals/loky/backend/popen_loky_posix.py", line 199, in <module>
    exitcode = process_obj._bootstrap()
  File "/LUSTRE/users/rnaveiro/.conda/envs/acra2/lib/python3.8/multiprocessing/process.py", line 335, in _bootstrap
    util._flush_std_streams()
  File "/LUSTRE/users/rnaveiro/.conda/envs/acra2/lib/python3.8/multiprocessing/util.py", line 416, in _flush_std_streams
    sys.stderr.flush()
FileNotFoundError: [Errno 2] No such file or directory


--------------------------------------------------------------------------------


--------------------------------------------------------------------------------
LokyProcess-4534 failed with traceback: 
--------------------------------------------------------------------------------
Traceback (most recent call last):
  File "/LUSTRE/users/rnaveiro/.conda/envs/acra2/lib/python3.8/site-packages/joblib/externals/loky/backend/popen_loky_posix.py", line 199, in <module>
    exitcode = process_obj._bootstrap()
  File "/LUSTRE/users/rnaveiro/.conda/envs/acra2/lib/python3.8/multiprocessing/process.py", line 335, in _bootstrap
    util._flush_std_streams()
  File "/LUSTRE/users/rnaveiro/.conda/envs/acra2/lib/python3.8/multiprocessing/util.py", line 416, in _flush_std_streams
    sys.stderr.flush()
FileNotFoundError: [Errno 2] No such file or directory


--------------------------------------------------------------------------------


--------------------------------------------------------------------------------
LokyProcess-4529 failed with traceback: 
--------------------------------------------------------------------------------
Traceback (most recent call last):
  File "/LUSTRE/users/rnaveiro/.conda/envs/acra2/lib/python3.8/site-packages/joblib/externals/loky/backend/popen_loky_posix.py", line 199, in <module>
    exitcode = process_obj._bootstrap()
  File "/LUSTRE/users/rnaveiro/.conda/envs/acra2/lib/python3.8/multiprocessing/process.py", line 335, in _bootstrap
    util._flush_std_streams()
  File "/LUSTRE/users/rnaveiro/.conda/envs/acra2/lib/python3.8/multiprocessing/util.py", line 416, in _flush_std_streams
    sys.stderr.flush()
FileNotFoundError: [Errno 2] No such file or directory


--------------------------------------------------------------------------------


--------------------------------------------------------------------------------
LokyProcess-4531 failed with traceback: 
--------------------------------------------------------------------------------
Traceback (most recent call last):
  File "/LUSTRE/users/rnaveiro/.conda/envs/acra2/lib/python3.8/site-packages/joblib/externals/loky/backend/popen_loky_posix.py", line 199, in <module>
    exitcode = process_obj._bootstrap()
  File "/LUSTRE/users/rnaveiro/.conda/envs/acra2/lib/python3.8/multiprocessing/process.py", line 335, in _bootstrap
    util._flush_std_streams()
  File "/LUSTRE/users/rnaveiro/.conda/envs/acra2/lib/python3.8/multiprocessing/util.py", line 416, in _flush_std_streams
    sys.stderr.flush()
FileNotFoundError: [Errno 2] No such file or directory


--------------------------------------------------------------------------------


--------------------------------------------------------------------------------
LokyProcess-4499 failed with traceback: 
--------------------------------------------------------------------------------
Traceback (most recent call last):
  File "/LUSTRE/users/rnaveiro/.conda/envs/acra2/lib/python3.8/site-packages/joblib/externals/loky/backend/popen_loky_posix.py", line 199, in <module>
    exitcode = process_obj._bootstrap()
  File "/LUSTRE/users/rnaveiro/.conda/envs/acra2/lib/python3.8/multiprocessing/process.py", line 335, in _bootstrap
    util._flush_std_streams()
  File "/LUSTRE/users/rnaveiro/.conda/envs/acra2/lib/python3.8/multiprocessing/util.py", line 416, in _flush_std_streams
    sys.stderr.flush()
FileNotFoundError: [Errno 2] No such file or directory


--------------------------------------------------------------------------------


--------------------------------------------------------------------------------
LokyProcess-4530 failed with traceback: 
--------------------------------------------------------------------------------
Traceback (most recent call last):
  File "/LUSTRE/users/rnaveiro/.conda/envs/acra2/lib/python3.8/site-packages/joblib/externals/loky/backend/popen_loky_posix.py", line 199, in <module>
    exitcode = process_obj._bootstrap()
  File "/LUSTRE/users/rnaveiro/.conda/envs/acra2/lib/python3.8/multiprocessing/process.py", line 335, in _bootstrap
    util._flush_std_streams()
  File "/LUSTRE/users/rnaveiro/.conda/envs/acra2/lib/python3.8/multiprocessing/util.py", line 416, in _flush_std_streams
    sys.stderr.flush()
FileNotFoundError: [Errno 2] No such file or directory


--------------------------------------------------------------------------------


--------------------------------------------------------------------------------
LokyProcess-4520 failed with traceback: 
--------------------------------------------------------------------------------
Traceback (most recent call last):
  File "/LUSTRE/users/rnaveiro/.conda/envs/acra2/lib/python3.8/site-packages/joblib/externals/loky/backend/popen_loky_posix.py", line 199, in <module>
    exitcode = process_obj._bootstrap()
  File "/LUSTRE/users/rnaveiro/.conda/envs/acra2/lib/python3.8/multiprocessing/process.py", line 335, in _bootstrap
    util._flush_std_streams()
  File "/LUSTRE/users/rnaveiro/.conda/envs/acra2/lib/python3.8/multiprocessing/util.py", line 416, in _flush_std_streams
    sys.stderr.flush()
FileNotFoundError: [Errno 2] No such file or directory


--------------------------------------------------------------------------------


--------------------------------------------------------------------------------
LokyProcess-4535 failed with traceback: 
--------------------------------------------------------------------------------
Traceback (most recent call last):
  File "/LUSTRE/users/rnaveiro/.conda/envs/acra2/lib/python3.8/site-packages/joblib/externals/loky/backend/popen_loky_posix.py", line 199, in <module>
    exitcode = process_obj._bootstrap()
  File "/LUSTRE/users/rnaveiro/.conda/envs/acra2/lib/python3.8/multiprocessing/process.py", line 335, in _bootstrap
    util._flush_std_streams()
  File "/LUSTRE/users/rnaveiro/.conda/envs/acra2/lib/python3.8/multiprocessing/util.py", line 416, in _flush_std_streams
    sys.stderr.flush()
FileNotFoundError: [Errno 2] No such file or directory


--------------------------------------------------------------------------------


--------------------------------------------------------------------------------
LokyProcess-4482 failed with traceback: 
--------------------------------------------------------------------------------
Traceback (most recent call last):
  File "/LUSTRE/users/rnaveiro/.conda/envs/acra2/lib/python3.8/site-packages/joblib/externals/loky/backend/popen_loky_posix.py", line 199, in <module>
    exitcode = process_obj._bootstrap()
  File "/LUSTRE/users/rnaveiro/.conda/envs/acra2/lib/python3.8/multiprocessing/process.py", line 335, in _bootstrap
    util._flush_std_streams()
  File "/LUSTRE/users/rnaveiro/.conda/envs/acra2/lib/python3.8/multiprocessing/util.py", line 416, in _flush_std_streams
    sys.stderr.flush()
FileNotFoundError: [Errno 2] No such file or directory


--------------------------------------------------------------------------------


--------------------------------------------------------------------------------
LokyProcess-4495 failed with traceback: 
--------------------------------------------------------------------------------
Traceback (most recent call last):
  File "/LUSTRE/users/rnaveiro/.conda/envs/acra2/lib/python3.8/site-packages/joblib/externals/loky/backend/popen_loky_posix.py", line 199, in <module>
    exitcode = process_obj._bootstrap()
  File "/LUSTRE/users/rnaveiro/.conda/envs/acra2/lib/python3.8/multiprocessing/process.py", line 335, in _bootstrap
    util._flush_std_streams()
  File "/LUSTRE/users/rnaveiro/.conda/envs/acra2/lib/python3.8/multiprocessing/util.py", line 416, in _flush_std_streams
    sys.stderr.flush()
FileNotFoundError: [Errno 2] No such file or directory


--------------------------------------------------------------------------------


--------------------------------------------------------------------------------
LokyProcess-4504 failed with traceback: 
--------------------------------------------------------------------------------
Traceback (most recent call last):
  File "/LUSTRE/users/rnaveiro/.conda/envs/acra2/lib/python3.8/site-packages/joblib/externals/loky/backend/popen_loky_posix.py", line 199, in <module>
    exitcode = process_obj._bootstrap()
  File "/LUSTRE/users/rnaveiro/.conda/envs/acra2/lib/python3.8/multiprocessing/process.py", line 335, in _bootstrap
    util._flush_std_streams()
  File "/LUSTRE/users/rnaveiro/.conda/envs/acra2/lib/python3.8/multiprocessing/util.py", line 416, in _flush_std_streams
    sys.stderr.flush()
FileNotFoundError: [Errno 2] No such file or directory


--------------------------------------------------------------------------------


--------------------------------------------------------------------------------
LokyProcess-4502 failed with traceback: 
--------------------------------------------------------------------------------
Traceback (most recent call last):
  File "/LUSTRE/users/rnaveiro/.conda/envs/acra2/lib/python3.8/site-packages/joblib/externals/loky/backend/popen_loky_posix.py", line 199, in <module>
    exitcode = process_obj._bootstrap()
  File "/LUSTRE/users/rnaveiro/.conda/envs/acra2/lib/python3.8/multiprocessing/process.py", line 335, in _bootstrap
    util._flush_std_streams()
  File "/LUSTRE/users/rnaveiro/.conda/envs/acra2/lib/python3.8/multiprocessing/util.py", line 416, in _flush_std_streams
    sys.stderr.flush()
FileNotFoundError: [Errno 2] No such file or directory


--------------------------------------------------------------------------------


--------------------------------------------------------------------------------
LokyProcess-4527 failed with traceback: 
--------------------------------------------------------------------------------
Traceback (most recent call last):
  File "/LUSTRE/users/rnaveiro/.conda/envs/acra2/lib/python3.8/site-packages/joblib/externals/loky/backend/popen_loky_posix.py", line 199, in <module>
    exitcode = process_obj._bootstrap()
  File "/LUSTRE/users/rnaveiro/.conda/envs/acra2/lib/python3.8/multiprocessing/process.py", line 335, in _bootstrap
    util._flush_std_streams()
  File "/LUSTRE/users/rnaveiro/.conda/envs/acra2/lib/python3.8/multiprocessing/util.py", line 416, in _flush_std_streams
    sys.stderr.flush()
FileNotFoundError: [Errno 2] No such file or directory


--------------------------------------------------------------------------------


--------------------------------------------------------------------------------
LokyProcess-4465 failed with traceback: 
--------------------------------------------------------------------------------
Traceback (most recent call last):
  File "/LUSTRE/users/rnaveiro/.conda/envs/acra2/lib/python3.8/site-packages/joblib/externals/loky/backend/popen_loky_posix.py", line 199, in <module>
    exitcode = process_obj._bootstrap()
  File "/LUSTRE/users/rnaveiro/.conda/envs/acra2/lib/python3.8/multiprocessing/process.py", line 335, in _bootstrap
    util._flush_std_streams()
  File "/LUSTRE/users/rnaveiro/.conda/envs/acra2/lib/python3.8/multiprocessing/util.py", line 416, in _flush_std_streams
    sys.stderr.flush()
FileNotFoundError: [Errno 2] No such file or directory


--------------------------------------------------------------------------------


--------------------------------------------------------------------------------
LokyProcess-4509 failed with traceback: 
--------------------------------------------------------------------------------
Traceback (most recent call last):
  File "/LUSTRE/users/rnaveiro/.conda/envs/acra2/lib/python3.8/site-packages/joblib/externals/loky/backend/popen_loky_posix.py", line 199, in <module>
    exitcode = process_obj._bootstrap()
  File "/LUSTRE/users/rnaveiro/.conda/envs/acra2/lib/python3.8/multiprocessing/process.py", line 335, in _bootstrap
    util._flush_std_streams()
  File "/LUSTRE/users/rnaveiro/.conda/envs/acra2/lib/python3.8/multiprocessing/util.py", line 416, in _flush_std_streams
    sys.stderr.flush()
FileNotFoundError: [Errno 2] No such file or directory


--------------------------------------------------------------------------------


--------------------------------------------------------------------------------
LokyProcess-4512 failed with traceback: 
--------------------------------------------------------------------------------
Traceback (most recent call last):
  File "/LUSTRE/users/rnaveiro/.conda/envs/acra2/lib/python3.8/site-packages/joblib/externals/loky/backend/popen_loky_posix.py", line 199, in <module>
    exitcode = process_obj._bootstrap()
  File "/LUSTRE/users/rnaveiro/.conda/envs/acra2/lib/python3.8/multiprocessing/process.py", line 335, in _bootstrap
    util._flush_std_streams()
  File "/LUSTRE/users/rnaveiro/.conda/envs/acra2/lib/python3.8/multiprocessing/util.py", line 416, in _flush_std_streams
    sys.stderr.flush()
FileNotFoundError: [Errno 2] No such file or directory


--------------------------------------------------------------------------------


--------------------------------------------------------------------------------
LokyProcess-4522 failed with traceback: 
--------------------------------------------------------------------------------
Traceback (most recent call last):
  File "/LUSTRE/users/rnaveiro/.conda/envs/acra2/lib/python3.8/site-packages/joblib/externals/loky/backend/popen_loky_posix.py", line 199, in <module>
    exitcode = process_obj._bootstrap()
  File "/LUSTRE/users/rnaveiro/.conda/envs/acra2/lib/python3.8/multiprocessing/process.py", line 335, in _bootstrap
    util._flush_std_streams()
  File "/LUSTRE/users/rnaveiro/.conda/envs/acra2/lib/python3.8/multiprocessing/util.py", line 416, in _flush_std_streams
    sys.stderr.flush()
FileNotFoundError: [Errno 2] No such file or directory


--------------------------------------------------------------------------------


--------------------------------------------------------------------------------
LokyProcess-4511 failed with traceback: 
--------------------------------------------------------------------------------
Traceback (most recent call last):
  File "/LUSTRE/users/rnaveiro/.conda/envs/acra2/lib/python3.8/site-packages/joblib/externals/loky/backend/popen_loky_posix.py", line 199, in <module>
    exitcode = process_obj._bootstrap()
  File "/LUSTRE/users/rnaveiro/.conda/envs/acra2/lib/python3.8/multiprocessing/process.py", line 335, in _bootstrap
    util._flush_std_streams()
  File "/LUSTRE/users/rnaveiro/.conda/envs/acra2/lib/python3.8/multiprocessing/util.py", line 416, in _flush_std_streams
    sys.stderr.flush()
FileNotFoundError: [Errno 2] No such file or directory


--------------------------------------------------------------------------------


--------------------------------------------------------------------------------
LokyProcess-4515 failed with traceback: 
--------------------------------------------------------------------------------
Traceback (most recent call last):
  File "/LUSTRE/users/rnaveiro/.conda/envs/acra2/lib/python3.8/site-packages/joblib/externals/loky/backend/popen_loky_posix.py", line 199, in <module>
    exitcode = process_obj._bootstrap()
  File "/LUSTRE/users/rnaveiro/.conda/envs/acra2/lib/python3.8/multiprocessing/process.py", line 335, in _bootstrap
    util._flush_std_streams()
  File "/LUSTRE/users/rnaveiro/.conda/envs/acra2/lib/python3.8/multiprocessing/util.py", line 416, in _flush_std_streams
    sys.stderr.flush()
FileNotFoundError: [Errno 2] No such file or directory


--------------------------------------------------------------------------------


--------------------------------------------------------------------------------
LokyProcess-4508 failed with traceback: 
--------------------------------------------------------------------------------
Traceback (most recent call last):
  File "/LUSTRE/users/rnaveiro/.conda/envs/acra2/lib/python3.8/site-packages/joblib/externals/loky/backend/popen_loky_posix.py", line 199, in <module>
    exitcode = process_obj._bootstrap()
  File "/LUSTRE/users/rnaveiro/.conda/envs/acra2/lib/python3.8/multiprocessing/process.py", line 335, in _bootstrap
    util._flush_std_streams()
  File "/LUSTRE/users/rnaveiro/.conda/envs/acra2/lib/python3.8/multiprocessing/util.py", line 416, in _flush_std_streams
    sys.stderr.flush()
FileNotFoundError: [Errno 2] No such file or directory


--------------------------------------------------------------------------------


--------------------------------------------------------------------------------
LokyProcess-4541 failed with traceback: 
--------------------------------------------------------------------------------
Traceback (most recent call last):
  File "/LUSTRE/users/rnaveiro/.conda/envs/acra2/lib/python3.8/site-packages/joblib/externals/loky/backend/popen_loky_posix.py", line 199, in <module>
    exitcode = process_obj._bootstrap()
  File "/LUSTRE/users/rnaveiro/.conda/envs/acra2/lib/python3.8/multiprocessing/process.py", line 335, in _bootstrap
    util._flush_std_streams()
  File "/LUSTRE/users/rnaveiro/.conda/envs/acra2/lib/python3.8/multiprocessing/util.py", line 416, in _flush_std_streams
    sys.stderr.flush()
FileNotFoundError: [Errno 2] No such file or directory


--------------------------------------------------------------------------------


--------------------------------------------------------------------------------
LokyProcess-4526 failed with traceback: 
--------------------------------------------------------------------------------
Traceback (most recent call last):
  File "/LUSTRE/users/rnaveiro/.conda/envs/acra2/lib/python3.8/site-packages/joblib/externals/loky/backend/popen_loky_posix.py", line 199, in <module>
    exitcode = process_obj._bootstrap()
  File "/LUSTRE/users/rnaveiro/.conda/envs/acra2/lib/python3.8/multiprocessing/process.py", line 335, in _bootstrap
    util._flush_std_streams()
  File "/LUSTRE/users/rnaveiro/.conda/envs/acra2/lib/python3.8/multiprocessing/util.py", line 416, in _flush_std_streams
    sys.stderr.flush()
FileNotFoundError: [Errno 2] No such file or directory


--------------------------------------------------------------------------------


--------------------------------------------------------------------------------
LokyProcess-4460 failed with traceback: 
--------------------------------------------------------------------------------
Traceback (most recent call last):
  File "/LUSTRE/users/rnaveiro/.conda/envs/acra2/lib/python3.8/site-packages/joblib/externals/loky/backend/popen_loky_posix.py", line 199, in <module>
    exitcode = process_obj._bootstrap()
  File "/LUSTRE/users/rnaveiro/.conda/envs/acra2/lib/python3.8/multiprocessing/process.py", line 335, in _bootstrap
    util._flush_std_streams()
  File "/LUSTRE/users/rnaveiro/.conda/envs/acra2/lib/python3.8/multiprocessing/util.py", line 416, in _flush_std_streams
    sys.stderr.flush()
FileNotFoundError: [Errno 2] No such file or directory


--------------------------------------------------------------------------------


--------------------------------------------------------------------------------
LokyProcess-4519 failed with traceback: 
--------------------------------------------------------------------------------
Traceback (most recent call last):
  File "/LUSTRE/users/rnaveiro/.conda/envs/acra2/lib/python3.8/site-packages/joblib/externals/loky/backend/popen_loky_posix.py", line 199, in <module>
    exitcode = process_obj._bootstrap()
  File "/LUSTRE/users/rnaveiro/.conda/envs/acra2/lib/python3.8/multiprocessing/process.py", line 335, in _bootstrap
    util._flush_std_streams()
  File "/LUSTRE/users/rnaveiro/.conda/envs/acra2/lib/python3.8/multiprocessing/util.py", line 416, in _flush_std_streams
    sys.stderr.flush()
FileNotFoundError: [Errno 2] No such file or directory


--------------------------------------------------------------------------------


--------------------------------------------------------------------------------
LokyProcess-4496 failed with traceback: 
--------------------------------------------------------------------------------
Traceback (most recent call last):
  File "/LUSTRE/users/rnaveiro/.conda/envs/acra2/lib/python3.8/site-packages/joblib/externals/loky/backend/popen_loky_posix.py", line 199, in <module>
    exitcode = process_obj._bootstrap()
  File "/LUSTRE/users/rnaveiro/.conda/envs/acra2/lib/python3.8/multiprocessing/process.py", line 335, in _bootstrap
    util._flush_std_streams()
  File "/LUSTRE/users/rnaveiro/.conda/envs/acra2/lib/python3.8/multiprocessing/util.py", line 416, in _flush_std_streams
    sys.stderr.flush()
FileNotFoundError: [Errno 2] No such file or directory


--------------------------------------------------------------------------------


--------------------------------------------------------------------------------
LokyProcess-4497 failed with traceback: 
--------------------------------------------------------------------------------
Traceback (most recent call last):
  File "/LUSTRE/users/rnaveiro/.conda/envs/acra2/lib/python3.8/site-packages/joblib/externals/loky/backend/popen_loky_posix.py", line 199, in <module>
    exitcode = process_obj._bootstrap()
  File "/LUSTRE/users/rnaveiro/.conda/envs/acra2/lib/python3.8/multiprocessing/process.py", line 335, in _bootstrap
    util._flush_std_streams()
  File "/LUSTRE/users/rnaveiro/.conda/envs/acra2/lib/python3.8/multiprocessing/util.py", line 416, in _flush_std_streams
    sys.stderr.flush()
FileNotFoundError: [Errno 2] No such file or directory


--------------------------------------------------------------------------------


--------------------------------------------------------------------------------
LokyProcess-4516 failed with traceback: 
--------------------------------------------------------------------------------
Traceback (most recent call last):
  File "/LUSTRE/users/rnaveiro/.conda/envs/acra2/lib/python3.8/site-packages/joblib/externals/loky/backend/popen_loky_posix.py", line 199, in <module>
    exitcode = process_obj._bootstrap()
  File "/LUSTRE/users/rnaveiro/.conda/envs/acra2/lib/python3.8/multiprocessing/process.py", line 335, in _bootstrap
    util._flush_std_streams()
  File "/LUSTRE/users/rnaveiro/.conda/envs/acra2/lib/python3.8/multiprocessing/util.py", line 416, in _flush_std_streams
    sys.stderr.flush()
FileNotFoundError: [Errno 2] No such file or directory


--------------------------------------------------------------------------------


--------------------------------------------------------------------------------
LokyProcess-4506 failed with traceback: 
--------------------------------------------------------------------------------
Traceback (most recent call last):
  File "/LUSTRE/users/rnaveiro/.conda/envs/acra2/lib/python3.8/site-packages/joblib/externals/loky/backend/popen_loky_posix.py", line 199, in <module>
    exitcode = process_obj._bootstrap()
  File "/LUSTRE/users/rnaveiro/.conda/envs/acra2/lib/python3.8/multiprocessing/process.py", line 335, in _bootstrap
    util._flush_std_streams()
  File "/LUSTRE/users/rnaveiro/.conda/envs/acra2/lib/python3.8/multiprocessing/util.py", line 416, in _flush_std_streams
    sys.stderr.flush()
FileNotFoundError: [Errno 2] No such file or directory


--------------------------------------------------------------------------------


--------------------------------------------------------------------------------
LokyProcess-4510 failed with traceback: 
--------------------------------------------------------------------------------
Traceback (most recent call last):
  File "/LUSTRE/users/rnaveiro/.conda/envs/acra2/lib/python3.8/site-packages/joblib/externals/loky/backend/popen_loky_posix.py", line 199, in <module>
    exitcode = process_obj._bootstrap()
  File "/LUSTRE/users/rnaveiro/.conda/envs/acra2/lib/python3.8/multiprocessing/process.py", line 335, in _bootstrap
    util._flush_std_streams()
  File "/LUSTRE/users/rnaveiro/.conda/envs/acra2/lib/python3.8/multiprocessing/util.py", line 416, in _flush_std_streams
    sys.stderr.flush()
FileNotFoundError: [Errno 2] No such file or directory


--------------------------------------------------------------------------------


--------------------------------------------------------------------------------
LokyProcess-4524 failed with traceback: 
--------------------------------------------------------------------------------
Traceback (most recent call last):
  File "/LUSTRE/users/rnaveiro/.conda/envs/acra2/lib/python3.8/site-packages/joblib/externals/loky/backend/popen_loky_posix.py", line 199, in <module>
    exitcode = process_obj._bootstrap()
  File "/LUSTRE/users/rnaveiro/.conda/envs/acra2/lib/python3.8/multiprocessing/process.py", line 335, in _bootstrap
    util._flush_std_streams()
  File "/LUSTRE/users/rnaveiro/.conda/envs/acra2/lib/python3.8/multiprocessing/util.py", line 416, in _flush_std_streams
    sys.stderr.flush()
FileNotFoundError: [Errno 2] No such file or directory


--------------------------------------------------------------------------------


--------------------------------------------------------------------------------
LokyProcess-4528 failed with traceback: 
--------------------------------------------------------------------------------
Traceback (most recent call last):
  File "/LUSTRE/users/rnaveiro/.conda/envs/acra2/lib/python3.8/site-packages/joblib/externals/loky/backend/popen_loky_posix.py", line 199, in <module>
    exitcode = process_obj._bootstrap()
  File "/LUSTRE/users/rnaveiro/.conda/envs/acra2/lib/python3.8/multiprocessing/process.py", line 335, in _bootstrap
    util._flush_std_streams()
  File "/LUSTRE/users/rnaveiro/.conda/envs/acra2/lib/python3.8/multiprocessing/util.py", line 416, in _flush_std_streams
    sys.stderr.flush()
FileNotFoundError: [Errno 2] No such file or directory


--------------------------------------------------------------------------------


--------------------------------------------------------------------------------
LokyProcess-4525 failed with traceback: 
--------------------------------------------------------------------------------
Traceback (most recent call last):
  File "/LUSTRE/users/rnaveiro/.conda/envs/acra2/lib/python3.8/site-packages/joblib/externals/loky/backend/popen_loky_posix.py", line 199, in <module>
    exitcode = process_obj._bootstrap()
  File "/LUSTRE/users/rnaveiro/.conda/envs/acra2/lib/python3.8/multiprocessing/process.py", line 335, in _bootstrap
    util._flush_std_streams()
  File "/LUSTRE/users/rnaveiro/.conda/envs/acra2/lib/python3.8/multiprocessing/util.py", line 416, in _flush_std_streams
    sys.stderr.flush()
FileNotFoundError: [Errno 2] No such file or directory


--------------------------------------------------------------------------------


--------------------------------------------------------------------------------
LokyProcess-4507 failed with traceback: 
--------------------------------------------------------------------------------
Traceback (most recent call last):
  File "/LUSTRE/users/rnaveiro/.conda/envs/acra2/lib/python3.8/site-packages/joblib/externals/loky/backend/popen_loky_posix.py", line 199, in <module>
    exitcode = process_obj._bootstrap()
  File "/LUSTRE/users/rnaveiro/.conda/envs/acra2/lib/python3.8/multiprocessing/process.py", line 335, in _bootstrap
    util._flush_std_streams()
  File "/LUSTRE/users/rnaveiro/.conda/envs/acra2/lib/python3.8/multiprocessing/util.py", line 416, in _flush_std_streams
    sys.stderr.flush()
FileNotFoundError: [Errno 2] No such file or directory


--------------------------------------------------------------------------------


--------------------------------------------------------------------------------
LokyProcess-4514 failed with traceback: 
--------------------------------------------------------------------------------
Traceback (most recent call last):
  File "/LUSTRE/users/rnaveiro/.conda/envs/acra2/lib/python3.8/site-packages/joblib/externals/loky/backend/popen_loky_posix.py", line 199, in <module>
    exitcode = process_obj._bootstrap()
  File "/LUSTRE/users/rnaveiro/.conda/envs/acra2/lib/python3.8/multiprocessing/process.py", line 335, in _bootstrap
    util._flush_std_streams()
  File "/LUSTRE/users/rnaveiro/.conda/envs/acra2/lib/python3.8/multiprocessing/util.py", line 416, in _flush_std_streams
    sys.stderr.flush()
FileNotFoundError: [Errno 2] No such file or directory


--------------------------------------------------------------------------------


--------------------------------------------------------------------------------
LokyProcess-4498 failed with traceback: 
--------------------------------------------------------------------------------
Traceback (most recent call last):
  File "/LUSTRE/users/rnaveiro/.conda/envs/acra2/lib/python3.8/site-packages/joblib/externals/loky/backend/popen_loky_posix.py", line 199, in <module>
    exitcode = process_obj._bootstrap()
  File "/LUSTRE/users/rnaveiro/.conda/envs/acra2/lib/python3.8/multiprocessing/process.py", line 335, in _bootstrap
    util._flush_std_streams()
  File "/LUSTRE/users/rnaveiro/.conda/envs/acra2/lib/python3.8/multiprocessing/util.py", line 416, in _flush_std_streams
    sys.stderr.flush()
FileNotFoundError: [Errno 2] No such file or directory


--------------------------------------------------------------------------------


--------------------------------------------------------------------------------
LokyProcess-4505 failed with traceback: 
--------------------------------------------------------------------------------
Traceback (most recent call last):
  File "/LUSTRE/users/rnaveiro/.conda/envs/acra2/lib/python3.8/site-packages/joblib/externals/loky/backend/popen_loky_posix.py", line 199, in <module>
    exitcode = process_obj._bootstrap()
  File "/LUSTRE/users/rnaveiro/.conda/envs/acra2/lib/python3.8/multiprocessing/process.py", line 335, in _bootstrap
    util._flush_std_streams()
  File "/LUSTRE/users/rnaveiro/.conda/envs/acra2/lib/python3.8/multiprocessing/util.py", line 416, in _flush_std_streams
    sys.stderr.flush()
FileNotFoundError: [Errno 2] No such file or directory


--------------------------------------------------------------------------------


--------------------------------------------------------------------------------
LokyProcess-4518 failed with traceback: 
--------------------------------------------------------------------------------
Traceback (most recent call last):
  File "/LUSTRE/users/rnaveiro/.conda/envs/acra2/lib/python3.8/site-packages/joblib/externals/loky/backend/popen_loky_posix.py", line 199, in <module>
    exitcode = process_obj._bootstrap()
  File "/LUSTRE/users/rnaveiro/.conda/envs/acra2/lib/python3.8/multiprocessing/process.py", line 335, in _bootstrap
    util._flush_std_streams()
  File "/LUSTRE/users/rnaveiro/.conda/envs/acra2/lib/python3.8/multiprocessing/util.py", line 416, in _flush_std_streams
    sys.stderr.flush()
FileNotFoundError: [Errno 2] No such file or directory


--------------------------------------------------------------------------------


--------------------------------------------------------------------------------
LokyProcess-4501 failed with traceback: 
--------------------------------------------------------------------------------
Traceback (most recent call last):
  File "/LUSTRE/users/rnaveiro/.conda/envs/acra2/lib/python3.8/site-packages/joblib/externals/loky/backend/popen_loky_posix.py", line 199, in <module>
    exitcode = process_obj._bootstrap()
  File "/LUSTRE/users/rnaveiro/.conda/envs/acra2/lib/python3.8/multiprocessing/process.py", line 335, in _bootstrap
    util._flush_std_streams()
  File "/LUSTRE/users/rnaveiro/.conda/envs/acra2/lib/python3.8/multiprocessing/util.py", line 416, in _flush_std_streams
    sys.stderr.flush()
FileNotFoundError: [Errno 2] No such file or directory


--------------------------------------------------------------------------------


--------------------------------------------------------------------------------
LokyProcess-4500 failed with traceback: 
--------------------------------------------------------------------------------
Traceback (most recent call last):
  File "/LUSTRE/users/rnaveiro/.conda/envs/acra2/lib/python3.8/site-packages/joblib/externals/loky/backend/popen_loky_posix.py", line 199, in <module>
    exitcode = process_obj._bootstrap()
  File "/LUSTRE/users/rnaveiro/.conda/envs/acra2/lib/python3.8/multiprocessing/process.py", line 335, in _bootstrap
    util._flush_std_streams()
  File "/LUSTRE/users/rnaveiro/.conda/envs/acra2/lib/python3.8/multiprocessing/util.py", line 416, in _flush_std_streams
    sys.stderr.flush()
FileNotFoundError: [Errno 2] No such file or directory


--------------------------------------------------------------------------------


--------------------------------------------------------------------------------
LokyProcess-4532 failed with traceback: 
--------------------------------------------------------------------------------
Traceback (most recent call last):
  File "/LUSTRE/users/rnaveiro/.conda/envs/acra2/lib/python3.8/site-packages/joblib/externals/loky/backend/popen_loky_posix.py", line 199, in <module>
    exitcode = process_obj._bootstrap()
  File "/LUSTRE/users/rnaveiro/.conda/envs/acra2/lib/python3.8/multiprocessing/process.py", line 335, in _bootstrap
    util._flush_std_streams()
  File "/LUSTRE/users/rnaveiro/.conda/envs/acra2/lib/python3.8/multiprocessing/util.py", line 416, in _flush_std_streams
    sys.stderr.flush()
FileNotFoundError: [Errno 2] No such file or directory


--------------------------------------------------------------------------------


--------------------------------------------------------------------------------
LokyProcess-4538 failed with traceback: 
--------------------------------------------------------------------------------
Traceback (most recent call last):
  File "/LUSTRE/users/rnaveiro/.conda/envs/acra2/lib/python3.8/site-packages/joblib/externals/loky/backend/popen_loky_posix.py", line 199, in <module>
    exitcode = process_obj._bootstrap()
  File "/LUSTRE/users/rnaveiro/.conda/envs/acra2/lib/python3.8/multiprocessing/process.py", line 335, in _bootstrap
    util._flush_std_streams()
  File "/LUSTRE/users/rnaveiro/.conda/envs/acra2/lib/python3.8/multiprocessing/util.py", line 416, in _flush_std_streams
    sys.stderr.flush()
FileNotFoundError: [Errno 2] No such file or directory


--------------------------------------------------------------------------------


--------------------------------------------------------------------------------
LokyProcess-4503 failed with traceback: 
--------------------------------------------------------------------------------
Traceback (most recent call last):
  File "/LUSTRE/users/rnaveiro/.conda/envs/acra2/lib/python3.8/site-packages/joblib/externals/loky/backend/popen_loky_posix.py", line 199, in <module>
    exitcode = process_obj._bootstrap()
  File "/LUSTRE/users/rnaveiro/.conda/envs/acra2/lib/python3.8/multiprocessing/process.py", line 335, in _bootstrap
    util._flush_std_streams()
  File "/LUSTRE/users/rnaveiro/.conda/envs/acra2/lib/python3.8/multiprocessing/util.py", line 416, in _flush_std_streams
    sys.stderr.flush()
FileNotFoundError: [Errno 2] No such file or directory


--------------------------------------------------------------------------------


--------------------------------------------------------------------------------
LokyProcess-4523 failed with traceback: 
--------------------------------------------------------------------------------
Traceback (most recent call last):
  File "/LUSTRE/users/rnaveiro/.conda/envs/acra2/lib/python3.8/site-packages/joblib/externals/loky/backend/popen_loky_posix.py", line 199, in <module>
    exitcode = process_obj._bootstrap()
  File "/LUSTRE/users/rnaveiro/.conda/envs/acra2/lib/python3.8/multiprocessing/process.py", line 335, in _bootstrap
    util._flush_std_streams()
  File "/LUSTRE/users/rnaveiro/.conda/envs/acra2/lib/python3.8/multiprocessing/util.py", line 416, in _flush_std_streams
    sys.stderr.flush()
FileNotFoundError: [Errno 2] No such file or directory


--------------------------------------------------------------------------------


--------------------------------------------------------------------------------
LokyProcess-4533 failed with traceback: 
--------------------------------------------------------------------------------
Traceback (most recent call last):
  File "/LUSTRE/users/rnaveiro/.conda/envs/acra2/lib/python3.8/site-packages/joblib/externals/loky/backend/popen_loky_posix.py", line 199, in <module>
    exitcode = process_obj._bootstrap()
  File "/LUSTRE/users/rnaveiro/.conda/envs/acra2/lib/python3.8/multiprocessing/process.py", line 335, in _bootstrap
    util._flush_std_streams()
  File "/LUSTRE/users/rnaveiro/.conda/envs/acra2/lib/python3.8/multiprocessing/util.py", line 416, in _flush_std_streams
    sys.stderr.flush()
FileNotFoundError: [Errno 2] No such file or directory


--------------------------------------------------------------------------------


--------------------------------------------------------------------------------
LokyProcess-4513 failed with traceback: 
--------------------------------------------------------------------------------
Traceback (most recent call last):
  File "/LUSTRE/users/rnaveiro/.conda/envs/acra2/lib/python3.8/site-packages/joblib/externals/loky/backend/popen_loky_posix.py", line 199, in <module>
    exitcode = process_obj._bootstrap()
  File "/LUSTRE/users/rnaveiro/.conda/envs/acra2/lib/python3.8/multiprocessing/process.py", line 335, in _bootstrap
    util._flush_std_streams()
  File "/LUSTRE/users/rnaveiro/.conda/envs/acra2/lib/python3.8/multiprocessing/util.py", line 416, in _flush_std_streams
    sys.stderr.flush()
FileNotFoundError: [Errno 2] No such file or directory


--------------------------------------------------------------------------------
nbACRA accuracy on tainted data var0.5 0.65
Classifier nn
nnaccuracy on clean data 0.75
nnaccuracy on tainted data 0.3333333333333333


--------------------------------------------------------------------------------
LokyProcess-4537 failed with traceback: 
--------------------------------------------------------------------------------
Traceback (most recent call last):
  File "/LUSTRE/users/rnaveiro/.conda/envs/acra2/lib/python3.8/site-packages/joblib/externals/loky/backend/popen_loky_posix.py", line 199, in <module>
    exitcode = process_obj._bootstrap()
  File "/LUSTRE/users/rnaveiro/.conda/envs/acra2/lib/python3.8/multiprocessing/process.py", line 335, in _bootstrap
    util._flush_std_streams()
  File "/LUSTRE/users/rnaveiro/.conda/envs/acra2/lib/python3.8/multiprocessing/util.py", line 416, in _flush_std_streams
    sys.stderr.flush()
FileNotFoundError: [Errno 2] No such file or directory


--------------------------------------------------------------------------------
nnACRA accuracy on tainted data var0 0.6583333333333333
nnACRA accuracy on tainted data var0.5 0.7
Classifier svm
svmaccuracy on clean data 0.7625
svmaccuracy on tainted data 0.32083333333333336
svmACRA accuracy on tainted data var0 0.45416666666666666
svmACRA accuracy on tainted data var0.5 0.4708333333333333
Classifier lr
lraccuracy on clean data 0.7625
lraccuracy on tainted data 0.3333333333333333
lrACRA accuracy on tainted data var0 0.5041666666666667
lrACRA accuracy on tainted data var0.5 0.5375
Classifier rf
rfaccuracy on clean data 0.7541666666666667
rfaccuracy on tainted data 0.3333333333333333
rfACRA accuracy on tainted data var0 0.6916666666666667
rfACRA accuracy on tainted data var0.5 0.7208333333333333
Writing Experiment  8
Experiment:  9
Classifier nb
nbaccuracy on clean data 0.725
nbaccuracy on tainted data 0.30416666666666664
nbACRA accuracy on tainted data var0 0.6541666666666667


--------------------------------------------------------------------------------
LokyProcess-5060 failed with traceback: 
--------------------------------------------------------------------------------
Traceback (most recent call last):
  File "/LUSTRE/users/rnaveiro/.conda/envs/acra2/lib/python3.8/site-packages/joblib/externals/loky/backend/popen_loky_posix.py", line 199, in <module>
    exitcode = process_obj._bootstrap()
  File "/LUSTRE/users/rnaveiro/.conda/envs/acra2/lib/python3.8/multiprocessing/process.py", line 335, in _bootstrap
    util._flush_std_streams()
  File "/LUSTRE/users/rnaveiro/.conda/envs/acra2/lib/python3.8/multiprocessing/util.py", line 416, in _flush_std_streams
    sys.stderr.flush()
FileNotFoundError: [Errno 2] No such file or directory


--------------------------------------------------------------------------------


--------------------------------------------------------------------------------
LokyProcess-5075 failed with traceback: 
--------------------------------------------------------------------------------
Traceback (most recent call last):
  File "/LUSTRE/users/rnaveiro/.conda/envs/acra2/lib/python3.8/site-packages/joblib/externals/loky/backend/popen_loky_posix.py", line 199, in <module>
    exitcode = process_obj._bootstrap()
  File "/LUSTRE/users/rnaveiro/.conda/envs/acra2/lib/python3.8/multiprocessing/process.py", line 335, in _bootstrap
    util._flush_std_streams()
  File "/LUSTRE/users/rnaveiro/.conda/envs/acra2/lib/python3.8/multiprocessing/util.py", line 416, in _flush_std_streams
    sys.stderr.flush()
FileNotFoundError: [Errno 2] No such file or directory


--------------------------------------------------------------------------------


--------------------------------------------------------------------------------
LokyProcess-5059 failed with traceback: 
--------------------------------------------------------------------------------
Traceback (most recent call last):
  File "/LUSTRE/users/rnaveiro/.conda/envs/acra2/lib/python3.8/site-packages/joblib/externals/loky/backend/popen_loky_posix.py", line 199, in <module>
    exitcode = process_obj._bootstrap()
  File "/LUSTRE/users/rnaveiro/.conda/envs/acra2/lib/python3.8/multiprocessing/process.py", line 335, in _bootstrap
    util._flush_std_streams()
  File "/LUSTRE/users/rnaveiro/.conda/envs/acra2/lib/python3.8/multiprocessing/util.py", line 416, in _flush_std_streams
    sys.stderr.flush()
FileNotFoundError: [Errno 2] No such file or directory


--------------------------------------------------------------------------------


--------------------------------------------------------------------------------
LokyProcess-5094 failed with traceback: 
--------------------------------------------------------------------------------
Traceback (most recent call last):
  File "/LUSTRE/users/rnaveiro/.conda/envs/acra2/lib/python3.8/site-packages/joblib/externals/loky/backend/popen_loky_posix.py", line 199, in <module>
    exitcode = process_obj._bootstrap()
  File "/LUSTRE/users/rnaveiro/.conda/envs/acra2/lib/python3.8/multiprocessing/process.py", line 335, in _bootstrap
    util._flush_std_streams()
  File "/LUSTRE/users/rnaveiro/.conda/envs/acra2/lib/python3.8/multiprocessing/util.py", line 416, in _flush_std_streams
    sys.stderr.flush()
FileNotFoundError: [Errno 2] No such file or directory


--------------------------------------------------------------------------------


--------------------------------------------------------------------------------
LokyProcess-5007 failed with traceback: 
--------------------------------------------------------------------------------
Traceback (most recent call last):
  File "/LUSTRE/users/rnaveiro/.conda/envs/acra2/lib/python3.8/site-packages/joblib/externals/loky/backend/popen_loky_posix.py", line 199, in <module>
    exitcode = process_obj._bootstrap()
  File "/LUSTRE/users/rnaveiro/.conda/envs/acra2/lib/python3.8/multiprocessing/process.py", line 335, in _bootstrap
    util._flush_std_streams()
  File "/LUSTRE/users/rnaveiro/.conda/envs/acra2/lib/python3.8/multiprocessing/util.py", line 416, in _flush_std_streams
    sys.stderr.flush()
FileNotFoundError: [Errno 2] No such file or directory


--------------------------------------------------------------------------------


--------------------------------------------------------------------------------
LokyProcess-5100 failed with traceback: 
--------------------------------------------------------------------------------
Traceback (most recent call last):
  File "/LUSTRE/users/rnaveiro/.conda/envs/acra2/lib/python3.8/site-packages/joblib/externals/loky/backend/popen_loky_posix.py", line 199, in <module>
    exitcode = process_obj._bootstrap()
  File "/LUSTRE/users/rnaveiro/.conda/envs/acra2/lib/python3.8/multiprocessing/process.py", line 335, in _bootstrap
    util._flush_std_streams()
  File "/LUSTRE/users/rnaveiro/.conda/envs/acra2/lib/python3.8/multiprocessing/util.py", line 416, in _flush_std_streams
    sys.stderr.flush()
FileNotFoundError: [Errno 2] No such file or directory


--------------------------------------------------------------------------------


--------------------------------------------------------------------------------
LokyProcess-5098 failed with traceback: 
--------------------------------------------------------------------------------
Traceback (most recent call last):
  File "/LUSTRE/users/rnaveiro/.conda/envs/acra2/lib/python3.8/site-packages/joblib/externals/loky/backend/popen_loky_posix.py", line 199, in <module>
    exitcode = process_obj._bootstrap()
  File "/LUSTRE/users/rnaveiro/.conda/envs/acra2/lib/python3.8/multiprocessing/process.py", line 335, in _bootstrap
    util._flush_std_streams()
  File "/LUSTRE/users/rnaveiro/.conda/envs/acra2/lib/python3.8/multiprocessing/util.py", line 416, in _flush_std_streams
    sys.stderr.flush()
FileNotFoundError: [Errno 2] No such file or directory


--------------------------------------------------------------------------------


--------------------------------------------------------------------------------
LokyProcess-5090 failed with traceback: 
--------------------------------------------------------------------------------
Traceback (most recent call last):
  File "/LUSTRE/users/rnaveiro/.conda/envs/acra2/lib/python3.8/site-packages/joblib/externals/loky/backend/popen_loky_posix.py", line 199, in <module>
    exitcode = process_obj._bootstrap()
  File "/LUSTRE/users/rnaveiro/.conda/envs/acra2/lib/python3.8/multiprocessing/process.py", line 335, in _bootstrap
    util._flush_std_streams()
  File "/LUSTRE/users/rnaveiro/.conda/envs/acra2/lib/python3.8/multiprocessing/util.py", line 416, in _flush_std_streams
    sys.stderr.flush()
FileNotFoundError: [Errno 2] No such file or directory


--------------------------------------------------------------------------------


--------------------------------------------------------------------------------
LokyProcess-5076 failed with traceback: 
--------------------------------------------------------------------------------
Traceback (most recent call last):
  File "/LUSTRE/users/rnaveiro/.conda/envs/acra2/lib/python3.8/site-packages/joblib/externals/loky/backend/popen_loky_posix.py", line 199, in <module>
    exitcode = process_obj._bootstrap()
  File "/LUSTRE/users/rnaveiro/.conda/envs/acra2/lib/python3.8/multiprocessing/process.py", line 335, in _bootstrap
    util._flush_std_streams()
  File "/LUSTRE/users/rnaveiro/.conda/envs/acra2/lib/python3.8/multiprocessing/util.py", line 416, in _flush_std_streams
    sys.stderr.flush()
FileNotFoundError: [Errno 2] No such file or directory


--------------------------------------------------------------------------------


--------------------------------------------------------------------------------
LokyProcess-5099 failed with traceback: 
--------------------------------------------------------------------------------
Traceback (most recent call last):
  File "/LUSTRE/users/rnaveiro/.conda/envs/acra2/lib/python3.8/site-packages/joblib/externals/loky/backend/popen_loky_posix.py", line 199, in <module>
    exitcode = process_obj._bootstrap()
  File "/LUSTRE/users/rnaveiro/.conda/envs/acra2/lib/python3.8/multiprocessing/process.py", line 335, in _bootstrap
    util._flush_std_streams()
  File "/LUSTRE/users/rnaveiro/.conda/envs/acra2/lib/python3.8/multiprocessing/util.py", line 416, in _flush_std_streams
    sys.stderr.flush()
FileNotFoundError: [Errno 2] No such file or directory


--------------------------------------------------------------------------------


--------------------------------------------------------------------------------
LokyProcess-5079 failed with traceback: 
--------------------------------------------------------------------------------
Traceback (most recent call last):
  File "/LUSTRE/users/rnaveiro/.conda/envs/acra2/lib/python3.8/site-packages/joblib/externals/loky/backend/popen_loky_posix.py", line 199, in <module>
    exitcode = process_obj._bootstrap()
  File "/LUSTRE/users/rnaveiro/.conda/envs/acra2/lib/python3.8/multiprocessing/process.py", line 335, in _bootstrap
    util._flush_std_streams()
  File "/LUSTRE/users/rnaveiro/.conda/envs/acra2/lib/python3.8/multiprocessing/util.py", line 416, in _flush_std_streams
    sys.stderr.flush()
FileNotFoundError: [Errno 2] No such file or directory


--------------------------------------------------------------------------------


--------------------------------------------------------------------------------
LokyProcess-5083 failed with traceback: 
--------------------------------------------------------------------------------
Traceback (most recent call last):
  File "/LUSTRE/users/rnaveiro/.conda/envs/acra2/lib/python3.8/site-packages/joblib/externals/loky/backend/popen_loky_posix.py", line 199, in <module>
    exitcode = process_obj._bootstrap()
  File "/LUSTRE/users/rnaveiro/.conda/envs/acra2/lib/python3.8/multiprocessing/process.py", line 335, in _bootstrap
    util._flush_std_streams()
  File "/LUSTRE/users/rnaveiro/.conda/envs/acra2/lib/python3.8/multiprocessing/util.py", line 416, in _flush_std_streams
    sys.stderr.flush()
FileNotFoundError: [Errno 2] No such file or directory


--------------------------------------------------------------------------------


--------------------------------------------------------------------------------
LokyProcess-5057 failed with traceback: 
--------------------------------------------------------------------------------
Traceback (most recent call last):
  File "/LUSTRE/users/rnaveiro/.conda/envs/acra2/lib/python3.8/site-packages/joblib/externals/loky/backend/popen_loky_posix.py", line 199, in <module>
    exitcode = process_obj._bootstrap()
  File "/LUSTRE/users/rnaveiro/.conda/envs/acra2/lib/python3.8/multiprocessing/process.py", line 335, in _bootstrap
    util._flush_std_streams()
  File "/LUSTRE/users/rnaveiro/.conda/envs/acra2/lib/python3.8/multiprocessing/util.py", line 416, in _flush_std_streams
    sys.stderr.flush()
FileNotFoundError: [Errno 2] No such file or directory


--------------------------------------------------------------------------------


--------------------------------------------------------------------------------
LokyProcess-5070 failed with traceback: 
--------------------------------------------------------------------------------
Traceback (most recent call last):
  File "/LUSTRE/users/rnaveiro/.conda/envs/acra2/lib/python3.8/site-packages/joblib/externals/loky/backend/popen_loky_posix.py", line 199, in <module>
    exitcode = process_obj._bootstrap()
  File "/LUSTRE/users/rnaveiro/.conda/envs/acra2/lib/python3.8/multiprocessing/process.py", line 335, in _bootstrap
    util._flush_std_streams()
  File "/LUSTRE/users/rnaveiro/.conda/envs/acra2/lib/python3.8/multiprocessing/util.py", line 416, in _flush_std_streams
    sys.stderr.flush()
FileNotFoundError: [Errno 2] No such file or directory


--------------------------------------------------------------------------------


--------------------------------------------------------------------------------
LokyProcess-5093 failed with traceback: 
--------------------------------------------------------------------------------
Traceback (most recent call last):
  File "/LUSTRE/users/rnaveiro/.conda/envs/acra2/lib/python3.8/site-packages/joblib/externals/loky/backend/popen_loky_posix.py", line 199, in <module>
    exitcode = process_obj._bootstrap()
  File "/LUSTRE/users/rnaveiro/.conda/envs/acra2/lib/python3.8/multiprocessing/process.py", line 335, in _bootstrap
    util._flush_std_streams()
  File "/LUSTRE/users/rnaveiro/.conda/envs/acra2/lib/python3.8/multiprocessing/util.py", line 416, in _flush_std_streams
    sys.stderr.flush()
FileNotFoundError: [Errno 2] No such file or directory


--------------------------------------------------------------------------------


--------------------------------------------------------------------------------
LokyProcess-5066 failed with traceback: 
--------------------------------------------------------------------------------
Traceback (most recent call last):
  File "/LUSTRE/users/rnaveiro/.conda/envs/acra2/lib/python3.8/site-packages/joblib/externals/loky/backend/popen_loky_posix.py", line 199, in <module>
    exitcode = process_obj._bootstrap()
  File "/LUSTRE/users/rnaveiro/.conda/envs/acra2/lib/python3.8/multiprocessing/process.py", line 335, in _bootstrap
    util._flush_std_streams()
  File "/LUSTRE/users/rnaveiro/.conda/envs/acra2/lib/python3.8/multiprocessing/util.py", line 416, in _flush_std_streams
    sys.stderr.flush()
FileNotFoundError: [Errno 2] No such file or directory


--------------------------------------------------------------------------------


--------------------------------------------------------------------------------
LokyProcess-5062 failed with traceback: 
--------------------------------------------------------------------------------
Traceback (most recent call last):
  File "/LUSTRE/users/rnaveiro/.conda/envs/acra2/lib/python3.8/site-packages/joblib/externals/loky/backend/popen_loky_posix.py", line 199, in <module>
    exitcode = process_obj._bootstrap()
  File "/LUSTRE/users/rnaveiro/.conda/envs/acra2/lib/python3.8/multiprocessing/process.py", line 335, in _bootstrap
    util._flush_std_streams()
  File "/LUSTRE/users/rnaveiro/.conda/envs/acra2/lib/python3.8/multiprocessing/util.py", line 416, in _flush_std_streams
    sys.stderr.flush()
FileNotFoundError: [Errno 2] No such file or directory


--------------------------------------------------------------------------------


--------------------------------------------------------------------------------
LokyProcess-5077 failed with traceback: 
--------------------------------------------------------------------------------
Traceback (most recent call last):
  File "/LUSTRE/users/rnaveiro/.conda/envs/acra2/lib/python3.8/site-packages/joblib/externals/loky/backend/popen_loky_posix.py", line 199, in <module>
    exitcode = process_obj._bootstrap()
  File "/LUSTRE/users/rnaveiro/.conda/envs/acra2/lib/python3.8/multiprocessing/process.py", line 335, in _bootstrap
    util._flush_std_streams()
  File "/LUSTRE/users/rnaveiro/.conda/envs/acra2/lib/python3.8/multiprocessing/util.py", line 416, in _flush_std_streams
    sys.stderr.flush()
FileNotFoundError: [Errno 2] No such file or directory


--------------------------------------------------------------------------------


--------------------------------------------------------------------------------
LokyProcess-5055 failed with traceback: 
--------------------------------------------------------------------------------
Traceback (most recent call last):
  File "/LUSTRE/users/rnaveiro/.conda/envs/acra2/lib/python3.8/site-packages/joblib/externals/loky/backend/popen_loky_posix.py", line 199, in <module>
    exitcode = process_obj._bootstrap()
  File "/LUSTRE/users/rnaveiro/.conda/envs/acra2/lib/python3.8/multiprocessing/process.py", line 335, in _bootstrap
    util._flush_std_streams()
  File "/LUSTRE/users/rnaveiro/.conda/envs/acra2/lib/python3.8/multiprocessing/util.py", line 416, in _flush_std_streams
    sys.stderr.flush()
FileNotFoundError: [Errno 2] No such file or directory


--------------------------------------------------------------------------------


--------------------------------------------------------------------------------
LokyProcess-5061 failed with traceback: 
--------------------------------------------------------------------------------
Traceback (most recent call last):
  File "/LUSTRE/users/rnaveiro/.conda/envs/acra2/lib/python3.8/site-packages/joblib/externals/loky/backend/popen_loky_posix.py", line 199, in <module>
    exitcode = process_obj._bootstrap()
  File "/LUSTRE/users/rnaveiro/.conda/envs/acra2/lib/python3.8/multiprocessing/process.py", line 335, in _bootstrap
    util._flush_std_streams()
  File "/LUSTRE/users/rnaveiro/.conda/envs/acra2/lib/python3.8/multiprocessing/util.py", line 416, in _flush_std_streams
    sys.stderr.flush()
FileNotFoundError: [Errno 2] No such file or directory


--------------------------------------------------------------------------------


--------------------------------------------------------------------------------
LokyProcess-5092 failed with traceback: 
--------------------------------------------------------------------------------
Traceback (most recent call last):
  File "/LUSTRE/users/rnaveiro/.conda/envs/acra2/lib/python3.8/site-packages/joblib/externals/loky/backend/popen_loky_posix.py", line 199, in <module>
    exitcode = process_obj._bootstrap()
  File "/LUSTRE/users/rnaveiro/.conda/envs/acra2/lib/python3.8/multiprocessing/process.py", line 335, in _bootstrap
    util._flush_std_streams()
  File "/LUSTRE/users/rnaveiro/.conda/envs/acra2/lib/python3.8/multiprocessing/util.py", line 416, in _flush_std_streams
    sys.stderr.flush()
FileNotFoundError: [Errno 2] No such file or directory


--------------------------------------------------------------------------------


--------------------------------------------------------------------------------
LokyProcess-5089 failed with traceback: 
--------------------------------------------------------------------------------
Traceback (most recent call last):
  File "/LUSTRE/users/rnaveiro/.conda/envs/acra2/lib/python3.8/site-packages/joblib/externals/loky/backend/popen_loky_posix.py", line 199, in <module>
    exitcode = process_obj._bootstrap()
  File "/LUSTRE/users/rnaveiro/.conda/envs/acra2/lib/python3.8/multiprocessing/process.py", line 335, in _bootstrap
    util._flush_std_streams()
  File "/LUSTRE/users/rnaveiro/.conda/envs/acra2/lib/python3.8/multiprocessing/util.py", line 416, in _flush_std_streams
    sys.stderr.flush()
FileNotFoundError: [Errno 2] No such file or directory


--------------------------------------------------------------------------------


--------------------------------------------------------------------------------
LokyProcess-5063 failed with traceback: 
--------------------------------------------------------------------------------
Traceback (most recent call last):
  File "/LUSTRE/users/rnaveiro/.conda/envs/acra2/lib/python3.8/site-packages/joblib/externals/loky/backend/popen_loky_posix.py", line 199, in <module>
    exitcode = process_obj._bootstrap()
  File "/LUSTRE/users/rnaveiro/.conda/envs/acra2/lib/python3.8/multiprocessing/process.py", line 335, in _bootstrap
    util._flush_std_streams()
  File "/LUSTRE/users/rnaveiro/.conda/envs/acra2/lib/python3.8/multiprocessing/util.py", line 416, in _flush_std_streams
    sys.stderr.flush()
FileNotFoundError: [Errno 2] No such file or directory


--------------------------------------------------------------------------------


--------------------------------------------------------------------------------
LokyProcess-5097 failed with traceback: 
--------------------------------------------------------------------------------
Traceback (most recent call last):
  File "/LUSTRE/users/rnaveiro/.conda/envs/acra2/lib/python3.8/site-packages/joblib/externals/loky/backend/popen_loky_posix.py", line 199, in <module>
    exitcode = process_obj._bootstrap()
  File "/LUSTRE/users/rnaveiro/.conda/envs/acra2/lib/python3.8/multiprocessing/process.py", line 335, in _bootstrap
    util._flush_std_streams()
  File "/LUSTRE/users/rnaveiro/.conda/envs/acra2/lib/python3.8/multiprocessing/util.py", line 416, in _flush_std_streams
    sys.stderr.flush()
FileNotFoundError: [Errno 2] No such file or directory


--------------------------------------------------------------------------------


--------------------------------------------------------------------------------
LokyProcess-5084 failed with traceback: 
--------------------------------------------------------------------------------
Traceback (most recent call last):
  File "/LUSTRE/users/rnaveiro/.conda/envs/acra2/lib/python3.8/site-packages/joblib/externals/loky/backend/popen_loky_posix.py", line 199, in <module>
    exitcode = process_obj._bootstrap()
  File "/LUSTRE/users/rnaveiro/.conda/envs/acra2/lib/python3.8/multiprocessing/process.py", line 335, in _bootstrap
    util._flush_std_streams()
  File "/LUSTRE/users/rnaveiro/.conda/envs/acra2/lib/python3.8/multiprocessing/util.py", line 416, in _flush_std_streams
    sys.stderr.flush()
FileNotFoundError: [Errno 2] No such file or directory


--------------------------------------------------------------------------------


--------------------------------------------------------------------------------
LokyProcess-5072 failed with traceback: 
--------------------------------------------------------------------------------
Traceback (most recent call last):
  File "/LUSTRE/users/rnaveiro/.conda/envs/acra2/lib/python3.8/site-packages/joblib/externals/loky/backend/popen_loky_posix.py", line 199, in <module>
    exitcode = process_obj._bootstrap()
  File "/LUSTRE/users/rnaveiro/.conda/envs/acra2/lib/python3.8/multiprocessing/process.py", line 335, in _bootstrap
    util._flush_std_streams()
  File "/LUSTRE/users/rnaveiro/.conda/envs/acra2/lib/python3.8/multiprocessing/util.py", line 416, in _flush_std_streams
    sys.stderr.flush()
FileNotFoundError: [Errno 2] No such file or directory


--------------------------------------------------------------------------------


--------------------------------------------------------------------------------
LokyProcess-5071 failed with traceback: 
--------------------------------------------------------------------------------
Traceback (most recent call last):
  File "/LUSTRE/users/rnaveiro/.conda/envs/acra2/lib/python3.8/site-packages/joblib/externals/loky/backend/popen_loky_posix.py", line 199, in <module>
    exitcode = process_obj._bootstrap()
  File "/LUSTRE/users/rnaveiro/.conda/envs/acra2/lib/python3.8/multiprocessing/process.py", line 335, in _bootstrap
    util._flush_std_streams()
  File "/LUSTRE/users/rnaveiro/.conda/envs/acra2/lib/python3.8/multiprocessing/util.py", line 416, in _flush_std_streams
    sys.stderr.flush()
FileNotFoundError: [Errno 2] No such file or directory


--------------------------------------------------------------------------------


--------------------------------------------------------------------------------
LokyProcess-5096 failed with traceback: 
--------------------------------------------------------------------------------
Traceback (most recent call last):
  File "/LUSTRE/users/rnaveiro/.conda/envs/acra2/lib/python3.8/site-packages/joblib/externals/loky/backend/popen_loky_posix.py", line 199, in <module>
    exitcode = process_obj._bootstrap()
  File "/LUSTRE/users/rnaveiro/.conda/envs/acra2/lib/python3.8/multiprocessing/process.py", line 335, in _bootstrap
    util._flush_std_streams()
  File "/LUSTRE/users/rnaveiro/.conda/envs/acra2/lib/python3.8/multiprocessing/util.py", line 416, in _flush_std_streams
    sys.stderr.flush()
FileNotFoundError: [Errno 2] No such file or directory


--------------------------------------------------------------------------------


--------------------------------------------------------------------------------
LokyProcess-5064 failed with traceback: 
--------------------------------------------------------------------------------
Traceback (most recent call last):
  File "/LUSTRE/users/rnaveiro/.conda/envs/acra2/lib/python3.8/site-packages/joblib/externals/loky/backend/popen_loky_posix.py", line 199, in <module>
    exitcode = process_obj._bootstrap()
  File "/LUSTRE/users/rnaveiro/.conda/envs/acra2/lib/python3.8/multiprocessing/process.py", line 335, in _bootstrap
    util._flush_std_streams()
  File "/LUSTRE/users/rnaveiro/.conda/envs/acra2/lib/python3.8/multiprocessing/util.py", line 416, in _flush_std_streams
    sys.stderr.flush()
FileNotFoundError: [Errno 2] No such file or directory


--------------------------------------------------------------------------------


--------------------------------------------------------------------------------
LokyProcess-5056 failed with traceback: 
--------------------------------------------------------------------------------
Traceback (most recent call last):
  File "/LUSTRE/users/rnaveiro/.conda/envs/acra2/lib/python3.8/site-packages/joblib/externals/loky/backend/popen_loky_posix.py", line 199, in <module>
    exitcode = process_obj._bootstrap()
  File "/LUSTRE/users/rnaveiro/.conda/envs/acra2/lib/python3.8/multiprocessing/process.py", line 335, in _bootstrap
    util._flush_std_streams()
  File "/LUSTRE/users/rnaveiro/.conda/envs/acra2/lib/python3.8/multiprocessing/util.py", line 416, in _flush_std_streams
    sys.stderr.flush()
FileNotFoundError: [Errno 2] No such file or directory


--------------------------------------------------------------------------------


--------------------------------------------------------------------------------
LokyProcess-5065 failed with traceback: 
--------------------------------------------------------------------------------
Traceback (most recent call last):
  File "/LUSTRE/users/rnaveiro/.conda/envs/acra2/lib/python3.8/site-packages/joblib/externals/loky/backend/popen_loky_posix.py", line 199, in <module>
    exitcode = process_obj._bootstrap()
  File "/LUSTRE/users/rnaveiro/.conda/envs/acra2/lib/python3.8/multiprocessing/process.py", line 335, in _bootstrap
    util._flush_std_streams()
  File "/LUSTRE/users/rnaveiro/.conda/envs/acra2/lib/python3.8/multiprocessing/util.py", line 416, in _flush_std_streams
    sys.stderr.flush()
FileNotFoundError: [Errno 2] No such file or directory


--------------------------------------------------------------------------------


--------------------------------------------------------------------------------
LokyProcess-5054 failed with traceback: 
--------------------------------------------------------------------------------
Traceback (most recent call last):
  File "/LUSTRE/users/rnaveiro/.conda/envs/acra2/lib/python3.8/site-packages/joblib/externals/loky/backend/popen_loky_posix.py", line 199, in <module>
    exitcode = process_obj._bootstrap()
  File "/LUSTRE/users/rnaveiro/.conda/envs/acra2/lib/python3.8/multiprocessing/process.py", line 335, in _bootstrap
    util._flush_std_streams()
  File "/LUSTRE/users/rnaveiro/.conda/envs/acra2/lib/python3.8/multiprocessing/util.py", line 416, in _flush_std_streams
    sys.stderr.flush()
FileNotFoundError: [Errno 2] No such file or directory


--------------------------------------------------------------------------------


--------------------------------------------------------------------------------
LokyProcess-5087 failed with traceback: 
--------------------------------------------------------------------------------
Traceback (most recent call last):
  File "/LUSTRE/users/rnaveiro/.conda/envs/acra2/lib/python3.8/site-packages/joblib/externals/loky/backend/popen_loky_posix.py", line 199, in <module>
    exitcode = process_obj._bootstrap()
  File "/LUSTRE/users/rnaveiro/.conda/envs/acra2/lib/python3.8/multiprocessing/process.py", line 335, in _bootstrap
    util._flush_std_streams()
  File "/LUSTRE/users/rnaveiro/.conda/envs/acra2/lib/python3.8/multiprocessing/util.py", line 416, in _flush_std_streams
    sys.stderr.flush()
FileNotFoundError: [Errno 2] No such file or directory


--------------------------------------------------------------------------------


--------------------------------------------------------------------------------
LokyProcess-5069 failed with traceback: 
--------------------------------------------------------------------------------
Traceback (most recent call last):
  File "/LUSTRE/users/rnaveiro/.conda/envs/acra2/lib/python3.8/site-packages/joblib/externals/loky/backend/popen_loky_posix.py", line 199, in <module>
    exitcode = process_obj._bootstrap()
  File "/LUSTRE/users/rnaveiro/.conda/envs/acra2/lib/python3.8/multiprocessing/process.py", line 335, in _bootstrap
    util._flush_std_streams()
  File "/LUSTRE/users/rnaveiro/.conda/envs/acra2/lib/python3.8/multiprocessing/util.py", line 416, in _flush_std_streams
    sys.stderr.flush()
FileNotFoundError: [Errno 2] No such file or directory


--------------------------------------------------------------------------------


--------------------------------------------------------------------------------
LokyProcess-5019 failed with traceback: 
--------------------------------------------------------------------------------
Traceback (most recent call last):
  File "/LUSTRE/users/rnaveiro/.conda/envs/acra2/lib/python3.8/site-packages/joblib/externals/loky/backend/popen_loky_posix.py", line 199, in <module>
    exitcode = process_obj._bootstrap()
  File "/LUSTRE/users/rnaveiro/.conda/envs/acra2/lib/python3.8/multiprocessing/process.py", line 335, in _bootstrap
    util._flush_std_streams()
  File "/LUSTRE/users/rnaveiro/.conda/envs/acra2/lib/python3.8/multiprocessing/util.py", line 416, in _flush_std_streams
    sys.stderr.flush()
FileNotFoundError: [Errno 2] No such file or directory


--------------------------------------------------------------------------------


--------------------------------------------------------------------------------
LokyProcess-5068 failed with traceback: 
--------------------------------------------------------------------------------
Traceback (most recent call last):
  File "/LUSTRE/users/rnaveiro/.conda/envs/acra2/lib/python3.8/site-packages/joblib/externals/loky/backend/popen_loky_posix.py", line 199, in <module>
    exitcode = process_obj._bootstrap()
  File "/LUSTRE/users/rnaveiro/.conda/envs/acra2/lib/python3.8/multiprocessing/process.py", line 335, in _bootstrap
    util._flush_std_streams()
  File "/LUSTRE/users/rnaveiro/.conda/envs/acra2/lib/python3.8/multiprocessing/util.py", line 416, in _flush_std_streams
    sys.stderr.flush()
FileNotFoundError: [Errno 2] No such file or directory


--------------------------------------------------------------------------------


--------------------------------------------------------------------------------
LokyProcess-5073 failed with traceback: 
--------------------------------------------------------------------------------
Traceback (most recent call last):
  File "/LUSTRE/users/rnaveiro/.conda/envs/acra2/lib/python3.8/site-packages/joblib/externals/loky/backend/popen_loky_posix.py", line 199, in <module>
    exitcode = process_obj._bootstrap()
  File "/LUSTRE/users/rnaveiro/.conda/envs/acra2/lib/python3.8/multiprocessing/process.py", line 335, in _bootstrap
    util._flush_std_streams()
  File "/LUSTRE/users/rnaveiro/.conda/envs/acra2/lib/python3.8/multiprocessing/util.py", line 416, in _flush_std_streams
    sys.stderr.flush()
FileNotFoundError: [Errno 2] No such file or directory


--------------------------------------------------------------------------------


--------------------------------------------------------------------------------
LokyProcess-5080 failed with traceback: 
--------------------------------------------------------------------------------
Traceback (most recent call last):
  File "/LUSTRE/users/rnaveiro/.conda/envs/acra2/lib/python3.8/site-packages/joblib/externals/loky/backend/popen_loky_posix.py", line 199, in <module>
    exitcode = process_obj._bootstrap()
  File "/LUSTRE/users/rnaveiro/.conda/envs/acra2/lib/python3.8/multiprocessing/process.py", line 335, in _bootstrap
    util._flush_std_streams()
  File "/LUSTRE/users/rnaveiro/.conda/envs/acra2/lib/python3.8/multiprocessing/util.py", line 416, in _flush_std_streams
    sys.stderr.flush()
FileNotFoundError: [Errno 2] No such file or directory


--------------------------------------------------------------------------------


--------------------------------------------------------------------------------
LokyProcess-5095 failed with traceback: 
--------------------------------------------------------------------------------
Traceback (most recent call last):
  File "/LUSTRE/users/rnaveiro/.conda/envs/acra2/lib/python3.8/site-packages/joblib/externals/loky/backend/popen_loky_posix.py", line 199, in <module>
    exitcode = process_obj._bootstrap()
  File "/LUSTRE/users/rnaveiro/.conda/envs/acra2/lib/python3.8/multiprocessing/process.py", line 335, in _bootstrap
    util._flush_std_streams()
  File "/LUSTRE/users/rnaveiro/.conda/envs/acra2/lib/python3.8/multiprocessing/util.py", line 416, in _flush_std_streams
    sys.stderr.flush()
FileNotFoundError: [Errno 2] No such file or directory


--------------------------------------------------------------------------------


--------------------------------------------------------------------------------
LokyProcess-5067 failed with traceback: 
--------------------------------------------------------------------------------
Traceback (most recent call last):
  File "/LUSTRE/users/rnaveiro/.conda/envs/acra2/lib/python3.8/site-packages/joblib/externals/loky/backend/popen_loky_posix.py", line 199, in <module>
    exitcode = process_obj._bootstrap()
  File "/LUSTRE/users/rnaveiro/.conda/envs/acra2/lib/python3.8/multiprocessing/process.py", line 335, in _bootstrap
    util._flush_std_streams()
  File "/LUSTRE/users/rnaveiro/.conda/envs/acra2/lib/python3.8/multiprocessing/util.py", line 416, in _flush_std_streams
    sys.stderr.flush()
FileNotFoundError: [Errno 2] No such file or directory


--------------------------------------------------------------------------------


--------------------------------------------------------------------------------
LokyProcess-5086 failed with traceback: 
--------------------------------------------------------------------------------
Traceback (most recent call last):
  File "/LUSTRE/users/rnaveiro/.conda/envs/acra2/lib/python3.8/site-packages/joblib/externals/loky/backend/popen_loky_posix.py", line 199, in <module>
    exitcode = process_obj._bootstrap()
  File "/LUSTRE/users/rnaveiro/.conda/envs/acra2/lib/python3.8/multiprocessing/process.py", line 335, in _bootstrap
    util._flush_std_streams()
  File "/LUSTRE/users/rnaveiro/.conda/envs/acra2/lib/python3.8/multiprocessing/util.py", line 416, in _flush_std_streams
    sys.stderr.flush()
FileNotFoundError: [Errno 2] No such file or directory


--------------------------------------------------------------------------------


--------------------------------------------------------------------------------
LokyProcess-5058 failed with traceback: 
--------------------------------------------------------------------------------
Traceback (most recent call last):
  File "/LUSTRE/users/rnaveiro/.conda/envs/acra2/lib/python3.8/site-packages/joblib/externals/loky/backend/popen_loky_posix.py", line 199, in <module>
    exitcode = process_obj._bootstrap()
  File "/LUSTRE/users/rnaveiro/.conda/envs/acra2/lib/python3.8/multiprocessing/process.py", line 335, in _bootstrap
    util._flush_std_streams()
  File "/LUSTRE/users/rnaveiro/.conda/envs/acra2/lib/python3.8/multiprocessing/util.py", line 416, in _flush_std_streams
    sys.stderr.flush()
FileNotFoundError: [Errno 2] No such file or directory


--------------------------------------------------------------------------------


--------------------------------------------------------------------------------
LokyProcess-5081 failed with traceback: 
--------------------------------------------------------------------------------
Traceback (most recent call last):
  File "/LUSTRE/users/rnaveiro/.conda/envs/acra2/lib/python3.8/site-packages/joblib/externals/loky/backend/popen_loky_posix.py", line 199, in <module>
    exitcode = process_obj._bootstrap()
  File "/LUSTRE/users/rnaveiro/.conda/envs/acra2/lib/python3.8/multiprocessing/process.py", line 335, in _bootstrap
    util._flush_std_streams()
  File "/LUSTRE/users/rnaveiro/.conda/envs/acra2/lib/python3.8/multiprocessing/util.py", line 416, in _flush_std_streams
    sys.stderr.flush()
FileNotFoundError: [Errno 2] No such file or directory


--------------------------------------------------------------------------------


--------------------------------------------------------------------------------
LokyProcess-5074 failed with traceback: 
--------------------------------------------------------------------------------
Traceback (most recent call last):
  File "/LUSTRE/users/rnaveiro/.conda/envs/acra2/lib/python3.8/site-packages/joblib/externals/loky/backend/popen_loky_posix.py", line 199, in <module>
    exitcode = process_obj._bootstrap()
  File "/LUSTRE/users/rnaveiro/.conda/envs/acra2/lib/python3.8/multiprocessing/process.py", line 335, in _bootstrap
    util._flush_std_streams()
  File "/LUSTRE/users/rnaveiro/.conda/envs/acra2/lib/python3.8/multiprocessing/util.py", line 416, in _flush_std_streams
    sys.stderr.flush()
FileNotFoundError: [Errno 2] No such file or directory


--------------------------------------------------------------------------------


--------------------------------------------------------------------------------
LokyProcess-5053 failed with traceback: 
--------------------------------------------------------------------------------
Traceback (most recent call last):
  File "/LUSTRE/users/rnaveiro/.conda/envs/acra2/lib/python3.8/site-packages/joblib/externals/loky/backend/popen_loky_posix.py", line 199, in <module>
    exitcode = process_obj._bootstrap()
  File "/LUSTRE/users/rnaveiro/.conda/envs/acra2/lib/python3.8/multiprocessing/process.py", line 335, in _bootstrap
    util._flush_std_streams()
  File "/LUSTRE/users/rnaveiro/.conda/envs/acra2/lib/python3.8/multiprocessing/util.py", line 416, in _flush_std_streams
    sys.stderr.flush()
FileNotFoundError: [Errno 2] No such file or directory


--------------------------------------------------------------------------------


--------------------------------------------------------------------------------
LokyProcess-5082 failed with traceback: 
--------------------------------------------------------------------------------
Traceback (most recent call last):
  File "/LUSTRE/users/rnaveiro/.conda/envs/acra2/lib/python3.8/site-packages/joblib/externals/loky/backend/popen_loky_posix.py", line 199, in <module>
    exitcode = process_obj._bootstrap()
  File "/LUSTRE/users/rnaveiro/.conda/envs/acra2/lib/python3.8/multiprocessing/process.py", line 335, in _bootstrap
    util._flush_std_streams()
  File "/LUSTRE/users/rnaveiro/.conda/envs/acra2/lib/python3.8/multiprocessing/util.py", line 416, in _flush_std_streams
    sys.stderr.flush()
FileNotFoundError: [Errno 2] No such file or directory


--------------------------------------------------------------------------------


--------------------------------------------------------------------------------
LokyProcess-5078 failed with traceback: 
--------------------------------------------------------------------------------
Traceback (most recent call last):
  File "/LUSTRE/users/rnaveiro/.conda/envs/acra2/lib/python3.8/site-packages/joblib/externals/loky/backend/popen_loky_posix.py", line 199, in <module>
    exitcode = process_obj._bootstrap()
  File "/LUSTRE/users/rnaveiro/.conda/envs/acra2/lib/python3.8/multiprocessing/process.py", line 335, in _bootstrap
    util._flush_std_streams()
  File "/LUSTRE/users/rnaveiro/.conda/envs/acra2/lib/python3.8/multiprocessing/util.py", line 416, in _flush_std_streams
    sys.stderr.flush()
FileNotFoundError: [Errno 2] No such file or directory


--------------------------------------------------------------------------------


--------------------------------------------------------------------------------
LokyProcess-5091 failed with traceback: 
--------------------------------------------------------------------------------
Traceback (most recent call last):
  File "/LUSTRE/users/rnaveiro/.conda/envs/acra2/lib/python3.8/site-packages/joblib/externals/loky/backend/popen_loky_posix.py", line 199, in <module>
    exitcode = process_obj._bootstrap()
  File "/LUSTRE/users/rnaveiro/.conda/envs/acra2/lib/python3.8/multiprocessing/process.py", line 335, in _bootstrap
    util._flush_std_streams()
  File "/LUSTRE/users/rnaveiro/.conda/envs/acra2/lib/python3.8/multiprocessing/util.py", line 416, in _flush_std_streams
    sys.stderr.flush()
FileNotFoundError: [Errno 2] No such file or directory


--------------------------------------------------------------------------------
nbACRA accuracy on tainted data var0.5 0.6541666666666667
Classifier nn
nnaccuracy on clean data 0.5291666666666667
nnaccuracy on tainted data 0.4708333333333333


--------------------------------------------------------------------------------
LokyProcess-5088 failed with traceback: 
--------------------------------------------------------------------------------
Traceback (most recent call last):
  File "/LUSTRE/users/rnaveiro/.conda/envs/acra2/lib/python3.8/site-packages/joblib/externals/loky/backend/popen_loky_posix.py", line 199, in <module>
    exitcode = process_obj._bootstrap()
  File "/LUSTRE/users/rnaveiro/.conda/envs/acra2/lib/python3.8/multiprocessing/process.py", line 335, in _bootstrap
    util._flush_std_streams()
  File "/LUSTRE/users/rnaveiro/.conda/envs/acra2/lib/python3.8/multiprocessing/util.py", line 416, in _flush_std_streams
    sys.stderr.flush()
FileNotFoundError: [Errno 2] No such file or directory


--------------------------------------------------------------------------------


--------------------------------------------------------------------------------
LokyProcess-5085 failed with traceback: 
--------------------------------------------------------------------------------
Traceback (most recent call last):
  File "/LUSTRE/users/rnaveiro/.conda/envs/acra2/lib/python3.8/site-packages/joblib/externals/loky/backend/popen_loky_posix.py", line 199, in <module>
    exitcode = process_obj._bootstrap()
  File "/LUSTRE/users/rnaveiro/.conda/envs/acra2/lib/python3.8/multiprocessing/process.py", line 335, in _bootstrap
    util._flush_std_streams()
  File "/LUSTRE/users/rnaveiro/.conda/envs/acra2/lib/python3.8/multiprocessing/util.py", line 416, in _flush_std_streams
    sys.stderr.flush()
FileNotFoundError: [Errno 2] No such file or directory


--------------------------------------------------------------------------------
nnACRA accuracy on tainted data var0 0.45416666666666666
nnACRA accuracy on tainted data var0.5 0.5625
Classifier svm
svmaccuracy on clean data 0.6875
svmaccuracy on tainted data 0.26666666666666666
svmACRA accuracy on tainted data var0 0.5541666666666667
svmACRA accuracy on tainted data var0.5 0.55
Classifier lr
lraccuracy on clean data 0.725
lraccuracy on tainted data 0.3
lrACRA accuracy on tainted data var0 0.4791666666666667
lrACRA accuracy on tainted data var0.5 0.5083333333333333
Classifier rf
rfaccuracy on clean data 0.7125
rfaccuracy on tainted data 0.29583333333333334
rfACRA accuracy on tainted data var0 0.7708333333333334
rfACRA accuracy on tainted data var0.5 0.7833333333333333
Writing Experiment  9
